Workbook

Sheet Forecast_Process
A1: Chemical | B1: Warehouse Stock (L) | C1: In Skids (L) | D1: Combined Stock (L) | E1: Daily Use (L/day) | F1: Days Left | G1: Stockout Date | H1: Order-By Date | I1: On Order / In Transit (L) | J1: Next ETA | K1: Status
A2: =Setup!$A$3 -> Demulsifier (89067) | B2: =SUMIFS(Warehouse_Log!$F$2:$F$4999,Warehouse_Log!$C$2:$C$4999,$A2,Warehouse_Log!$B$2:$B$4999,"IN",Warehouse_Log!$K$2:$K$4999,"<>No")-SUMIFS(Warehouse_Log!$F$2:$F$4999,Warehouse_Log!$C$2:$C$4999,$A2,Warehouse_Log!$B$2:$B$4999,"OUT") -> 9000 | C2: =SUMIF(Tank_Levels!$B$2:$B$41,$A2,Tank_Levels!$I$2:$I$41) -> 1222.8 | D2: =$B2+$C2 -> 10222.8 | E2: =SUMIF(Tank_Levels!$B$2:$B$41,$A2,Tank_Levels!$D$2:$D$41) -> 120 | F2: =IF($E2=0,"",$D2/$E2) -> 85.19 | G2: =IF($F2="","",TODAY()+$F2) -> 46364.19 | H2: =IF($G2="","",$G2-Setup!$C$3) -> 46343.19 | I2: =SUMIFS(Warehouse_Log!$F$2:$F$4999,Warehouse_Log!$C$2:$C$4999,$A2,Warehouse_Log!$B$2:$B$4999,"IN",Warehouse_Log!$K$2:$K$4999,"No") -> 0 | J2: =IF(IFERROR(_xlfn.MINIFS(Warehouse_Log!$J$2:$J$4999,Warehouse_Log!$C$2:$C$4999,$A2,Warehouse_Log!$B$2:$B$4999,"IN",Warehouse_Log!$K$2:$K$4999,"No"),0)=0,"",IFERROR(_xlfn.MINIFS(Warehouse_Log!$J$2:$J$4999,Warehouse_Log!$C$2:$C$4999,$A2,Warehouse_Log!$B$2:$B$4999,"IN",Warehouse_Log!$K$2:$K$4999,"No"),0)) | K2: =IF($E2=0,"Stock only",IF(AND($H2<>"",$H2<=TODAY()),"ORDER NOW",IF(AND($I2>0,IFERROR(_xlfn.MINIFS(Warehouse_Log!$J$2:$J$4999,Warehouse_Log!$C$2:$C$4999,$A2,Warehouse_Log!$B$2:$B$4999,"IN",Warehouse_Log!$K$2:$K$4999,"No"),0)<>0,IFERROR(_xlfn.MINIFS(Warehouse_Log!$J$2:$J$4999,Warehouse_Log!$C$2:$C$4999,$A2,Warehouse_Log!$B$2:$B$4999,"IN",Warehouse_Log!$K$2:$K$4999,"No"),0)<=$G2),"Covered - arriving "&TEXT(IFERROR(_xlfn.MINIFS(Warehouse_Log!$J$2:$J$4999,Warehouse_Log!$C$2:$C$4999,$A2,Warehouse_Log!$B$2:$B$4999,"IN",Warehouse_Log!$K$2:$K$4999,"No"),0),"mmm dd"),IF(AND($H2<>"",($H2-TODAY())<=7),"Order soon","OK")))) -> OK
A3: =Setup!$A$4 -> Anti-Foam (DF-9000) | B3: =SUMIFS(Warehouse_Log!$F$2:$F$4999,Warehouse_Log!$C$2:$C$4999,$A3,Warehouse_Log!$B$2:$B$4999,"IN",Warehouse_Log!$K$2:$K$4999,"<>No")-SUMIFS(Warehouse_Log!$F$2:$F$4999,Warehouse_Log!$C$2:$C$4999,$A3,Warehouse_Log!$B$2:$B$4999,"OUT") -> 1200 | C3: =SUMIF(Tank_Levels!$B$2:$B$41,$A3,Tank_Levels!$I$2:$I$41) -> 150 | D3: =$B3+$C3 -> 1350 | E3: =SUMIF(Tank_Levels!$B$2:$B$41,$A3,Tank_Levels!$D$2:$D$41) -> 0 | F3: =IF($E3=0,"",$D3/$E3) | G3: =IF($F3="","",TODAY()+$F3) | H3: =IF($G3="","",$G3-Setup!$C$4) | I3: =SUMIFS(Warehouse_Log!$F$2:$F$4999,Warehouse_Log!$C$2:$C$4999,$A3,Warehouse_Log!$B$2:$B$4999,"IN",Warehouse_Log!$K$2:$K$4999,"No") -> 0 | J3: =IF(IFERROR(_xlfn.MINIFS(Warehouse_Log!$J$2:$J$4999,Warehouse_Log!$C$2:$C$4999,$A3,Warehouse_Log!$B$2:$B$4999,"IN",Warehouse_Log!$K$2:$K$4999,"No"),0)=0,"",IFERROR(_xlfn.MINIFS(Warehouse_Log!$J$2:$J$4999,Warehouse_Log!$C$2:$C$4999,$A3,Warehouse_Log!$B$2:$B$4999,"IN",Warehouse_Log!$K$2:$K$4999,"No"),0)) | K3: =IF($E3=0,"Stock only",IF(AND($H3<>"",$H3<=TODAY()),"ORDER NOW",IF(AND($I3>0,IFERROR(_xlfn.MINIFS(Warehouse_Log!$J$2:$J$4999,Warehouse_Log!$C$2:$C$4999,$A3,Warehouse_Log!$B$2:$B$4999,"IN",Warehouse_Log!$K$2:$K$4999,"No"),0)<>0,IFERROR(_xlfn.MINIFS(Warehouse_Log!$J$2:$J$4999,Warehouse_Log!$C$2:$C$4999,$A3,Warehouse_Log!$B$2:$B$4999,"IN",Warehouse_Log!$K$2:$K$4999,"No"),0)<=$G3),"Covered - arriving "&TEXT(IFERROR(_xlfn.MINIFS(Warehouse_Log!$J$2:$J$4999,Warehouse_Log!$C$2:$C$4999,$A3,Warehouse_Log!$B$2:$B$4999,"IN",Warehouse_Log!$K$2:$K$4999,"No"),0),"mmm dd"),IF(AND($H3<>"",($H3-TODAY())<=7),"Order soon","OK")))) -> Stock only
A4: =Setup!$A$5 -> Scale Inhibitor (SI-44108) | B4: =SUMIFS(Warehouse_Log!$F$2:$F$4999,Warehouse_Log!$C$2:$C$4999,$A4,Warehouse_Log!$B$2:$B$4999,"IN",Warehouse_Log!$K$2:$K$4999,"<>No")-SUMIFS(Warehouse_Log!$F$2:$F$4999,Warehouse_Log!$C$2:$C$4999,$A4,Warehouse_Log!$B$2:$B$4999,"OUT") -> 800 | C4: =SUMIF(Tank_Levels!$B$2:$B$41,$A4,Tank_Levels!$I$2:$I$41) -> 955.39223 | D4: =$B4+$C4 -> 1755.3922 | E4: =SUMIF(Tank_Levels!$B$2:$B$41,$A4,Tank_Levels!$D$2:$D$41) -> 29.04 | F4: =IF($E4=0,"",$D4/$E4) -> 60.447391 | G4: =IF($F4="","",TODAY()+$F4) -> 46339.447 | H4: =IF($G4="","",$G4-Setup!$C$5) -> 46318.447 | I4: =SUMIFS(Warehouse_Log!$F$2:$F$4999,Warehouse_Log!$C$2:$C$4999,$A4,Warehouse_Log!$B$2:$B$4999,"IN",Warehouse_Log!$K$2:$K$4999,"No") -> 0 | J4: =IF(IFERROR(_xlfn.MINIFS(Warehouse_Log!$J$2:$J$4999,Warehouse_Log!$C$2:$C$4999,$A4,Warehouse_Log!$B$2:$B$4999,"IN",Warehouse_Log!$K$2:$K$4999,"No"),0)=0,"",IFERROR(_xlfn.MINIFS(Warehouse_Log!$J$2:$J$4999,Warehouse_Log!$C$2:$C$4999,$A4,Warehouse_Log!$B$2:$B$4999,"IN",Warehouse_Log!$K$2:$K$4999,"No"),0)) | K4: =IF($E4=0,"Stock only",IF(AND($H4<>"",$H4<=TODAY()),"ORDER NOW",IF(AND($I4>0,IFERROR(_xlfn.MINIFS(Warehouse_Log!$J$2:$J$4999,Warehouse_Log!$C$2:$C$4999,$A4,Warehouse_Log!$B$2:$B$4999,"IN",Warehouse_Log!$K$2:$K$4999,"No"),0)<>0,IFERROR(_xlfn.MINIFS(Warehouse_Log!$J$2:$J$4999,Warehouse_Log!$C$2:$C$4999,$A4,Warehouse_Log!$B$2:$B$4999,"IN",Warehouse_Log!$K$2:$K$4999,"No"),0)<=$G4),"Covered - arriving "&TEXT(IFERROR(_xlfn.MINIFS(Warehouse_Log!$J$2:$J$4999,Warehouse_Log!$C$2:$C$4999,$A4,Warehouse_Log!$B$2:$B$4999,"IN",Warehouse_Log!$K$2:$K$4999,"No"),0),"mmm dd"),IF(AND($H4<>"",($H4-TODAY())<=7),"Order soon","OK")))) -> OK
A5: =Setup!$A$6 -> Paraffin Inhibitor PI-75135 | B5: =SUMIFS(Warehouse_Log!$F$2:$F$4999,Warehouse_Log!$C$2:$C$4999,$A5,Warehouse_Log!$B$2:$B$4999,"IN",Warehouse_Log!$K$2:$K$4999,"<>No")-SUMIFS(Warehouse_Log!$F$2:$F$4999,Warehouse_Log!$C$2:$C$4999,$A5,Warehouse_Log!$B$2:$B$4999,"OUT") -> 8000 | C5: =SUMIF(Tank_Levels!$B$2:$B$41,$A5,Tank_Levels!$I$2:$I$41) -> 0 | D5: =$B5+$C5 -> 8000 | E5: =SUMIF(Tank_Levels!$B$2:$B$41,$A5,Tank_Levels!$D$2:$D$41) -> 0 | F5: =IF($E5=0,"",$D5/$E5) | G5: =IF($F5="","",TODAY()+$F5) | H5: =IF($G5="","",$G5-Setup!$C$6) | I5: =SUMIFS(Warehouse_Log!$F$2:$F$4999,Warehouse_Log!$C$2:$C$4999,$A5,Warehouse_Log!$B$2:$B$4999,"IN",Warehouse_Log!$K$2:$K$4999,"No") -> 0 | J5: =IF(IFERROR(_xlfn.MINIFS(Warehouse_Log!$J$2:$J$4999,Warehouse_Log!$C$2:$C$4999,$A5,Warehouse_Log!$B$2:$B$4999,"IN",Warehouse_Log!$K$2:$K$4999,"No"),0)=0,"",IFERROR(_xlfn.MINIFS(Warehouse_Log!$J$2:$J$4999,Warehouse_Log!$C$2:$C$4999,$A5,Warehouse_Log!$B$2:$B$4999,"IN",Warehouse_Log!$K$2:$K$4999,"No"),0)) | K5: =IF($E5=0,"Stock only",IF(AND($H5<>"",$H5<=TODAY()),"ORDER NOW",IF(AND($I5>0,IFERROR(_xlfn.MINIFS(Warehouse_Log!$J$2:$J$4999,Warehouse_Log!$C$2:$C$4999,$A5,Warehouse_Log!$B$2:$B$4999,"IN",Warehouse_Log!$K$2:$K$4999,"No"),0)<>0,IFERROR(_xlfn.MINIFS(Warehouse_Log!$J$2:$J$4999,Warehouse_Log!$C$2:$C$4999,$A5,Warehouse_Log!$B$2:$B$4999,"IN",Warehouse_Log!$K$2:$K$4999,"No"),0)<=$G5),"Covered - arriving "&TEXT(IFERROR(_xlfn.MINIFS(Warehouse_Log!$J$2:$J$4999,Warehouse_Log!$C$2:$C$4999,$A5,Warehouse_Log!$B$2:$B$4999,"IN",Warehouse_Log!$K$2:$K$4999,"No"),0),"mmm dd"),IF(AND($H5<>"",($H5-TODAY())<=7),"Order soon","OK")))) -> Stock only
A6: =Setup!$A$7 -> Paraffin WI-301 | B6: =SUMIFS(Warehouse_Log!$F$2:$F$4999,Warehouse_Log!$C$2:$C$4999,$A6,Warehouse_Log!$B$2:$B$4999,"IN",Warehouse_Log!$K$2:$K$4999,"<>No")-SUMIFS(Warehouse_Log!$F$2:$F$4999,Warehouse_Log!$C$2:$C$4999,$A6,Warehouse_Log!$B$2:$B$4999,"OUT") -> 800 | C6: =SUMIF(Tank_Levels!$B$2:$B$41,$A6,Tank_Levels!$I$2:$I$41) -> 0 | D6: =$B6+$C6 -> 800 | E6: =SUMIF(Tank_Levels!$B$2:$B$41,$A6,Tank_Levels!$D$2:$D$41) -> 0 | F6: =IF($E6=0,"",$D6/$E6) | G6: =IF($F6="","",TODAY()+$F6) | H6: =IF($G6="","",$G6-Setup!$C$7) | I6: =SUMIFS(Warehouse_Log!$F$2:$F$4999,Warehouse_Log!$C$2:$C$4999,$A6,Warehouse_Log!$B$2:$B$4999,"IN",Warehouse_Log!$K$2:$K$4999,"No") -> 0 | J6: =IF(IFERROR(_xlfn.MINIFS(Warehouse_Log!$J$2:$J$4999,Warehouse_Log!$C$2:$C$4999,$A6,Warehouse_Log!$B$2:$B$4999,"IN",Warehouse_Log!$K$2:$K$4999,"No"),0)=0,"",IFERROR(_xlfn.MINIFS(Warehouse_Log!$J$2:$J$4999,Warehouse_Log!$C$2:$C$4999,$A6,Warehouse_Log!$B$2:$B$4999,"IN",Warehouse_Log!$K$2:$K$4999,"No"),0)) | K6: =IF($E6=0,"Stock only",IF(AND($H6<>"",$H6<=TODAY()),"ORDER NOW",IF(AND($I6>0,IFERROR(_xlfn.MINIFS(Warehouse_Log!$J$2:$J$4999,Warehouse_Log!$C$2:$C$4999,$A6,Warehouse_Log!$B$2:$B$4999,"IN",Warehouse_Log!$K$2:$K$4999,"No"),0)<>0,IFERROR(_xlfn.MINIFS(Warehouse_Log!$J$2:$J$4999,Warehouse_Log!$C$2:$C$4999,$A6,Warehouse_Log!$B$2:$B$4999,"IN",Warehouse_Log!$K$2:$K$4999,"No"),0)<=$G6),"Covered - arriving "&TEXT(IFERROR(_xlfn.MINIFS(Warehouse_Log!$J$2:$J$4999,Warehouse_Log!$C$2:$C$4999,$A6,Warehouse_Log!$B$2:$B$4999,"IN",Warehouse_Log!$K$2:$K$4999,"No"),0),"mmm dd"),IF(AND($H6<>"",($H6-TODAY())<=7),"Order soon","OK")))) -> Stock only
A7: =Setup!$A$8 -> Biocide (MB-5207) | B7: =SUMIFS(Warehouse_Log!$F$2:$F$4999,Warehouse_Log!$C$2:$C$4999,$A7,Warehouse_Log!$B$2:$B$4999,"IN",Warehouse_Log!$K$2:$K$4999,"<>No")-SUMIFS(Warehouse_Log!$F$2:$F$4999,Warehouse_Log!$C$2:$C$4999,$A7,Warehouse_Log!$B$2:$B$4999,"OUT") -> 0 | C7: =SUMIF(Tank_Levels!$B$2:$B$41,$A7,Tank_Levels!$I$2:$I$41) -> 359.15444 | D7: =$B7+$C7 -> 359.15444 | E7: =SUMIF(Tank_Levels!$B$2:$B$41,$A7,Tank_Levels!$D$2:$D$41) -> 7.9285714 | F7: =IF($E7=0,"",$D7/$E7) -> 45.298758 | G7: =IF($F7="","",TODAY()+$F7) -> 46324.299 | H7: =IF($G7="","",$G7-Setup!$C$8) -> 46303.299 | I7: =SUMIFS(Warehouse_Log!$F$2:$F$4999,Warehouse_Log!$C$2:$C$4999,$A7,Warehouse_Log!$B$2:$B$4999,"IN",Warehouse_Log!$K$2:$K$4999,"No") -> 800 | J7: =IF(IFERROR(_xlfn.MINIFS(Warehouse_Log!$J$2:$J$4999,Warehouse_Log!$C$2:$C$4999,$A7,Warehouse_Log!$B$2:$B$4999,"IN",Warehouse_Log!$K$2:$K$4999,"No"),0)=0,"",IFERROR(_xlfn.MINIFS(Warehouse_Log!$J$2:$J$4999,Warehouse_Log!$C$2:$C$4999,$A7,Warehouse_Log!$B$2:$B$4999,"IN",Warehouse_Log!$K$2:$K$4999,"No"),0)) -> 46283 | K7: =IF($E7=0,"Stock only",IF(AND($H7<>"",$H7<=TODAY()),"ORDER NOW",IF(AND($I7>0,IFERROR(_xlfn.MINIFS(Warehouse_Log!$J$2:$J$4999,Warehouse_Log!$C$2:$C$4999,$A7,Warehouse_Log!$B$2:$B$4999,"IN",Warehouse_Log!$K$2:$K$4999,"No"),0)<>0,IFERROR(_xlfn.MINIFS(Warehouse_Log!$J$2:$J$4999,Warehouse_Log!$C$2:$C$4999,$A7,Warehouse_Log!$B$2:$B$4999,"IN",Warehouse_Log!$K$2:$K$4999,"No"),0)<=$G7),"Covered - arriving "&TEXT(IFERROR(_xlfn.MINIFS(Warehouse_Log!$J$2:$J$4999,Warehouse_Log!$C$2:$C$4999,$A7,Warehouse_Log!$B$2:$B$4999,"IN",Warehouse_Log!$K$2:$K$4999,"No"),0),"mmm dd"),IF(AND($H7<>"",($H7-TODAY())<=7),"Order soon","OK")))) -> Covered - arriving Sep 18
A8: =Setup!$A$9 -> Corrosion Inhibitor (KI-34154) | B8: =SUMIFS(Warehouse_Log!$F$2:$F$4999,Warehouse_Log!$C$2:$C$4999,$A8,Warehouse_Log!$B$2:$B$4999,"IN",Warehouse_Log!$K$2:$K$4999,"<>No")-SUMIFS(Warehouse_Log!$F$2:$F$4999,Warehouse_Log!$C$2:$C$4999,$A8,Warehouse_Log!$B$2:$B$4999,"OUT") -> 0 | C8: =SUMIF(Tank_Levels!$B$2:$B$41,$A8,Tank_Levels!$I$2:$I$41) -> 1311.9228 | D8: =$B8+$C8 -> 1311.9228 | E8: =SUMIF(Tank_Levels!$B$2:$B$41,$A8,Tank_Levels!$D$2:$D$41) -> 117.35993 | F8: =IF($E8=0,"",$D8/$E8) -> 11.178626 | G8: =IF($F8="","",TODAY()+$F8) -> 46290.179 | H8: =IF($G8="","",$G8-Setup!$C$9) -> 46269.179 | I8: =SUMIFS(Warehouse_Log!$F$2:$F$4999,Warehouse_Log!$C$2:$C$4999,$A8,Warehouse_Log!$B$2:$B$4999,"IN",Warehouse_Log!$K$2:$K$4999,"No") -> 18000 | J8: =IF(IFERROR(_xlfn.MINIFS(Warehouse_Log!$J$2:$J$4999,Warehouse_Log!$C$2:$C$4999,$A8,Warehouse_Log!$B$2:$B$4999,"IN",Warehouse_Log!$K$2:$K$4999,"No"),0)=0,"",IFERROR(_xlfn.MINIFS(Warehouse_Log!$J$2:$J$4999,Warehouse_Log!$C$2:$C$4999,$A8,Warehouse_Log!$B$2:$B$4999,"IN",Warehouse_Log!$K$2:$K$4999,"No"),0)) -> 46283 | K8: =IF($E8=0,"Stock only",IF(AND($H8<>"",$H8<=TODAY()),"ORDER NOW",IF(AND($I8>0,IFERROR(_xlfn.MINIFS(Warehouse_Log!$J$2:$J$4999,Warehouse_Log!$C$2:$C$4999,$A8,Warehouse_Log!$B$2:$B$4999,"IN",Warehouse_Log!$K$2:$K$4999,"No"),0)<>0,IFERROR(_xlfn.MINIFS(Warehouse_Log!$J$2:$J$4999,Warehouse_Log!$C$2:$C$4999,$A8,Warehouse_Log!$B$2:$B$4999,"IN",Warehouse_Log!$K$2:$K$4999,"No"),0)<=$G8),"Covered - arriving "&TEXT(IFERROR(_xlfn.MINIFS(Warehouse_Log!$J$2:$J$4999,Warehouse_Log!$C$2:$C$4999,$A8,Warehouse_Log!$B$2:$B$4999,"IN",Warehouse_Log!$K$2:$K$4999,"No"),0),"mmm dd"),IF(AND($H8<>"",($H8-TODAY())<=7),"Order soon","OK")))) -> ORDER NOW
A9: =Setup!$A$10 -> Flocculant | B9: =SUMIFS(Warehouse_Log!$F$2:$F$4999,Warehouse_Log!$C$2:$C$4999,$A9,Warehouse_Log!$B$2:$B$4999,"IN",Warehouse_Log!$K$2:$K$4999,"<>No")-SUMIFS(Warehouse_Log!$F$2:$F$4999,Warehouse_Log!$C$2:$C$4999,$A9,Warehouse_Log!$B$2:$B$4999,"OUT") -> 0 | C9: =SUMIF(Tank_Levels!$B$2:$B$41,$A9,Tank_Levels!$I$2:$I$41) -> 37.782414 | D9: =$B9+$C9 -> 37.782414 | E9: =SUMIF(Tank_Levels!$B$2:$B$41,$A9,Tank_Levels!$D$2:$D$41) -> 6 | F9: =IF($E9=0,"",$D9/$E9) -> 6.2970691 | G9: =IF($F9="","",TODAY()+$F9) -> 46285.297 | H9: =IF($G9="","",$G9-Setup!$C$10) -> 46264.297 | I9: =SUMIFS(Warehouse_Log!$F$2:$F$4999,Warehouse_Log!$C$2:$C$4999,$A9,Warehouse_Log!$B$2:$B$4999,"IN",Warehouse_Log!$K$2:$K$4999,"No") -> 0 | J9: =IF(IFERROR(_xlfn.MINIFS(Warehouse_Log!$J$2:$J$4999,Warehouse_Log!$C$2:$C$4999,$A9,Warehouse_Log!$B$2:$B$4999,"IN",Warehouse_Log!$K$2:$K$4999,"No"),0)=0,"",IFERROR(_xlfn.MINIFS(Warehouse_Log!$J$2:$J$4999,Warehouse_Log!$C$2:$C$4999,$A9,Warehouse_Log!$B$2:$B$4999,"IN",Warehouse_Log!$K$2:$K$4999,"No"),0)) | K9: =IF($E9=0,"Stock only",IF(AND($H9<>"",$H9<=TODAY()),"ORDER NOW",IF(AND($I9>0,IFERROR(_xlfn.MINIFS(Warehouse_Log!$J$2:$J$4999,Warehouse_Log!$C$2:$C$4999,$A9,Warehouse_Log!$B$2:$B$4999,"IN",Warehouse_Log!$K$2:$K$4999,"No"),0)<>0,IFERROR(_xlfn.MINIFS(Warehouse_Log!$J$2:$J$4999,Warehouse_Log!$C$2:$C$4999,$A9,Warehouse_Log!$B$2:$B$4999,"IN",Warehouse_Log!$K$2:$K$4999,"No"),0)<=$G9),"Covered - arriving "&TEXT(IFERROR(_xlfn.MINIFS(Warehouse_Log!$J$2:$J$4999,Warehouse_Log!$C$2:$C$4999,$A9,Warehouse_Log!$B$2:$B$4999,"IN",Warehouse_Log!$K$2:$K$4999,"No"),0),"mmm dd"),IF(AND($H9<>"",($H9-TODAY())<=7),"Order soon","OK")))) -> ORDER NOW

Sheet Forecast_Lab
A1: Chemical | B1: Warehouse Stock (L) | C1: In Skids (L) | D1: Combined Stock (L) | E1: Daily Use (L/day) | F1: Days Left | G1: Stockout Date | H1: Order-By Date | I1: On Order / In Transit (L) | J1: Next ETA | K1: Status
A2: =Setup!$A$11 -> HCl 33% | B2: =SUMIFS(Warehouse_Log!$F$2:$F$4999,Warehouse_Log!$C$2:$C$4999,$A2,Warehouse_Log!$B$2:$B$4999,"IN",Warehouse_Log!$K$2:$K$4999,"<>No")-SUMIFS(Warehouse_Log!$F$2:$F$4999,Warehouse_Log!$C$2:$C$4999,$A2,Warehouse_Log!$B$2:$B$4999,"OUT") -> 720 | C2: =SUMIF(Tank_Levels!$B$2:$B$41,$A2,Tank_Levels!$I$2:$I$41) -> 0 | D2: =$B2+$C2 -> 720 | E2: =SUMIF(Tank_Levels!$B$2:$B$41,$A2,Tank_Levels!$D$2:$D$41) -> 0 | F2: =IF($E2=0,"",$D2/$E2) | G2: =IF($F2="","",TODAY()+$F2) | H2: =IF($G2="","",$G2-Setup!$C$11) | I2: =SUMIFS(Warehouse_Log!$F$2:$F$4999,Warehouse_Log!$C$2:$C$4999,$A2,Warehouse_Log!$B$2:$B$4999,"IN",Warehouse_Log!$K$2:$K$4999,"No") -> 0 | J2: =IF(IFERROR(_xlfn.MINIFS(Warehouse_Log!$J$2:$J$4999,Warehouse_Log!$C$2:$C$4999,$A2,Warehouse_Log!$B$2:$B$4999,"IN",Warehouse_Log!$K$2:$K$4999,"No"),0)=0,"",IFERROR(_xlfn.MINIFS(Warehouse_Log!$J$2:$J$4999,Warehouse_Log!$C$2:$C$4999,$A2,Warehouse_Log!$B$2:$B$4999,"IN",Warehouse_Log!$K$2:$K$4999,"No"),0)) | K2: =IF($E2=0,"Stock only",IF(AND($H2<>"",$H2<=TODAY()),"ORDER NOW",IF(AND($I2>0,IFERROR(_xlfn.MINIFS(Warehouse_Log!$J$2:$J$4999,Warehouse_Log!$C$2:$C$4999,$A2,Warehouse_Log!$B$2:$B$4999,"IN",Warehouse_Log!$K$2:$K$4999,"No"),0)<>0,IFERROR(_xlfn.MINIFS(Warehouse_Log!$J$2:$J$4999,Warehouse_Log!$C$2:$C$4999,$A2,Warehouse_Log!$B$2:$B$4999,"IN",Warehouse_Log!$K$2:$K$4999,"No"),0)<=$G2),"Covered - arriving "&TEXT(IFERROR(_xlfn.MINIFS(Warehouse_Log!$J$2:$J$4999,Warehouse_Log!$C$2:$C$4999,$A2,Warehouse_Log!$B$2:$B$4999,"IN",Warehouse_Log!$K$2:$K$4999,"No"),0),"mmm dd"),IF(AND($H2<>"",($H2-TODAY())<=7),"Order soon","OK")))) -> Stock only
A3: =Setup!$A$12 -> Industrial Salt | B3: =SUMIFS(Warehouse_Log!$F$2:$F$4999,Warehouse_Log!$C$2:$C$4999,$A3,Warehouse_Log!$B$2:$B$4999,"IN",Warehouse_Log!$K$2:$K$4999,"<>No")-SUMIFS(Warehouse_Log!$F$2:$F$4999,Warehouse_Log!$C$2:$C$4999,$A3,Warehouse_Log!$B$2:$B$4999,"OUT") -> 57.5 | C3: =SUMIF(Tank_Levels!$B$2:$B$41,$A3,Tank_Levels!$I$2:$I$41) -> 0 | D3: =$B3+$C3 -> 57.5 | E3: =SUMIF(Tank_Levels!$B$2:$B$41,$A3,Tank_Levels!$D$2:$D$41) -> 0 | F3: =IF($E3=0,"",$D3/$E3) | G3: =IF($F3="","",TODAY()+$F3) | H3: =IF($G3="","",$G3-Setup!$C$12) | I3: =SUMIFS(Warehouse_Log!$F$2:$F$4999,Warehouse_Log!$C$2:$C$4999,$A3,Warehouse_Log!$B$2:$B$4999,"IN",Warehouse_Log!$K$2:$K$4999,"No") -> 0 | J3: =IF(IFERROR(_xlfn.MINIFS(Warehouse_Log!$J$2:$J$4999,Warehouse_Log!$C$2:$C$4999,$A3,Warehouse_Log!$B$2:$B$4999,"IN",Warehouse_Log!$K$2:$K$4999,"No"),0)=0,"",IFERROR(_xlfn.MINIFS(Warehouse_Log!$J$2:$J$4999,Warehouse_Log!$C$2:$C$4999,$A3,Warehouse_Log!$B$2:$B$4999,"IN",Warehouse_Log!$K$2:$K$4999,"No"),0)) | K3: =IF($E3=0,"Stock only",IF(AND($H3<>"",$H3<=TODAY()),"ORDER NOW",IF(AND($I3>0,IFERROR(_xlfn.MINIFS(Warehouse_Log!$J$2:$J$4999,Warehouse_Log!$C$2:$C$4999,$A3,Warehouse_Log!$B$2:$B$4999,"IN",Warehouse_Log!$K$2:$K$4999,"No"),0)<>0,IFERROR(_xlfn.MINIFS(Warehouse_Log!$J$2:$J$4999,Warehouse_Log!$C$2:$C$4999,$A3,Warehouse_Log!$B$2:$B$4999,"IN",Warehouse_Log!$K$2:$K$4999,"No"),0)<=$G3),"Covered - arriving "&TEXT(IFERROR(_xlfn.MINIFS(Warehouse_Log!$J$2:$J$4999,Warehouse_Log!$C$2:$C$4999,$A3,Warehouse_Log!$B$2:$B$4999,"IN",Warehouse_Log!$K$2:$K$4999,"No"),0),"mmm dd"),IF(AND($H3<>"",($H3-TODAY())<=7),"Order soon","OK")))) -> Stock only
A4: =Setup!$A$13 -> N-Hexane | B4: =SUMIFS(Warehouse_Log!$F$2:$F$4999,Warehouse_Log!$C$2:$C$4999,$A4,Warehouse_Log!$B$2:$B$4999,"IN",Warehouse_Log!$K$2:$K$4999,"<>No")-SUMIFS(Warehouse_Log!$F$2:$F$4999,Warehouse_Log!$C$2:$C$4999,$A4,Warehouse_Log!$B$2:$B$4999,"OUT") -> 10 | C4: =SUMIF(Tank_Levels!$B$2:$B$41,$A4,Tank_Levels!$I$2:$I$41) -> 0 | D4: =$B4+$C4 -> 10 | E4: =SUMIF(Tank_Levels!$B$2:$B$41,$A4,Tank_Levels!$D$2:$D$41) -> 0 | F4: =IF($E4=0,"",$D4/$E4) | G4: =IF($F4="","",TODAY()+$F4) | H4: =IF($G4="","",$G4-Setup!$C$13) | I4: =SUMIFS(Warehouse_Log!$F$2:$F$4999,Warehouse_Log!$C$2:$C$4999,$A4,Warehouse_Log!$B$2:$B$4999,"IN",Warehouse_Log!$K$2:$K$4999,"No") -> 0 | J4: =IF(IFERROR(_xlfn.MINIFS(Warehouse_Log!$J$2:$J$4999,Warehouse_Log!$C$2:$C$4999,$A4,Warehouse_Log!$B$2:$B$4999,"IN",Warehouse_Log!$K$2:$K$4999,"No"),0)=0,"",IFERROR(_xlfn.MINIFS(Warehouse_Log!$J$2:$J$4999,Warehouse_Log!$C$2:$C$4999,$A4,Warehouse_Log!$B$2:$B$4999,"IN",Warehouse_Log!$K$2:$K$4999,"No"),0)) | K4: =IF($E4=0,"Stock only",IF(AND($H4<>"",$H4<=TODAY()),"ORDER NOW",IF(AND($I4>0,IFERROR(_xlfn.MINIFS(Warehouse_Log!$J$2:$J$4999,Warehouse_Log!$C$2:$C$4999,$A4,Warehouse_Log!$B$2:$B$4999,"IN",Warehouse_Log!$K$2:$K$4999,"No"),0)<>0,IFERROR(_xlfn.MINIFS(Warehouse_Log!$J$2:$J$4999,Warehouse_Log!$C$2:$C$4999,$A4,Warehouse_Log!$B$2:$B$4999,"IN",Warehouse_Log!$K$2:$K$4999,"No"),0)<=$G4),"Covered - arriving "&TEXT(IFERROR(_xlfn.MINIFS(Warehouse_Log!$J$2:$J$4999,Warehouse_Log!$C$2:$C$4999,$A4,Warehouse_Log!$B$2:$B$4999,"IN",Warehouse_Log!$K$2:$K$4999,"No"),0),"mmm dd"),IF(AND($H4<>"",($H4-TODAY())<=7),"Order soon","OK")))) -> Stock only
A5: =Setup!$A$14 -> 1-Butanol | B5: =SUMIFS(Warehouse_Log!$F$2:$F$4999,Warehouse_Log!$C$2:$C$4999,$A5,Warehouse_Log!$B$2:$B$4999,"IN",Warehouse_Log!$K$2:$K$4999,"<>No")-SUMIFS(Warehouse_Log!$F$2:$F$4999,Warehouse_Log!$C$2:$C$4999,$A5,Warehouse_Log!$B$2:$B$4999,"OUT") -> 60 | C5: =SUMIF(Tank_Levels!$B$2:$B$41,$A5,Tank_Levels!$I$2:$I$41) -> 0 | D5: =$B5+$C5 -> 60 | E5: =SUMIF(Tank_Levels!$B$2:$B$41,$A5,Tank_Levels!$D$2:$D$41) -> 0 | F5: =IF($E5=0,"",$D5/$E5) | G5: =IF($F5="","",TODAY()+$F5) | H5: =IF($G5="","",$G5-Setup!$C$14) | I5: =SUMIFS(Warehouse_Log!$F$2:$F$4999,Warehouse_Log!$C$2:$C$4999,$A5,Warehouse_Log!$B$2:$B$4999,"IN",Warehouse_Log!$K$2:$K$4999,"No") -> 0 | J5: =IF(IFERROR(_xlfn.MINIFS(Warehouse_Log!$J$2:$J$4999,Warehouse_Log!$C$2:$C$4999,$A5,Warehouse_Log!$B$2:$B$4999,"IN",Warehouse_Log!$K$2:$K$4999,"No"),0)=0,"",IFERROR(_xlfn.MINIFS(Warehouse_Log!$J$2:$J$4999,Warehouse_Log!$C$2:$C$4999,$A5,Warehouse_Log!$B$2:$B$4999,"IN",Warehouse_Log!$K$2:$K$4999,"No"),0)) | K5: =IF($E5=0,"Stock only",IF(AND($H5<>"",$H5<=TODAY()),"ORDER NOW",IF(AND($I5>0,IFERROR(_xlfn.MINIFS(Warehouse_Log!$J$2:$J$4999,Warehouse_Log!$C$2:$C$4999,$A5,Warehouse_Log!$B$2:$B$4999,"IN",Warehouse_Log!$K$2:$K$4999,"No"),0)<>0,IFERROR(_xlfn.MINIFS(Warehouse_Log!$J$2:$J$4999,Warehouse_Log!$C$2:$C$4999,$A5,Warehouse_Log!$B$2:$B$4999,"IN",Warehouse_Log!$K$2:$K$4999,"No"),0)<=$G5),"Covered - arriving "&TEXT(IFERROR(_xlfn.MINIFS(Warehouse_Log!$J$2:$J$4999,Warehouse_Log!$C$2:$C$4999,$A5,Warehouse_Log!$B$2:$B$4999,"IN",Warehouse_Log!$K$2:$K$4999,"No"),0),"mmm dd"),IF(AND($H5<>"",($H5-TODAY())<=7),"Order soon","OK")))) -> Stock only
A6: =Setup!$A$15 -> Acetone | B6: =SUMIFS(Warehouse_Log!$F$2:$F$4999,Warehouse_Log!$C$2:$C$4999,$A6,Warehouse_Log!$B$2:$B$4999,"IN",Warehouse_Log!$K$2:$K$4999,"<>No")-SUMIFS(Warehouse_Log!$F$2:$F$4999,Warehouse_Log!$C$2:$C$4999,$A6,Warehouse_Log!$B$2:$B$4999,"OUT") -> 7.5 | C6: =SUMIF(Tank_Levels!$B$2:$B$41,$A6,Tank_Levels!$I$2:$I$41) -> 0 | D6: =$B6+$C6 -> 7.5 | E6: =SUMIF(Tank_Levels!$B$2:$B$41,$A6,Tank_Levels!$D$2:$D$41) -> 0 | F6: =IF($E6=0,"",$D6/$E6) | G6: =IF($F6="","",TODAY()+$F6) | H6: =IF($G6="","",$G6-Setup!$C$15) | I6: =SUMIFS(Warehouse_Log!$F$2:$F$4999,Warehouse_Log!$C$2:$C$4999,$A6,Warehouse_Log!$B$2:$B$4999,"IN",Warehouse_Log!$K$2:$K$4999,"No") -> 0 | J6: =IF(IFERROR(_xlfn.MINIFS(Warehouse_Log!$J$2:$J$4999,Warehouse_Log!$C$2:$C$4999,$A6,Warehouse_Log!$B$2:$B$4999,"IN",Warehouse_Log!$K$2:$K$4999,"No"),0)=0,"",IFERROR(_xlfn.MINIFS(Warehouse_Log!$J$2:$J$4999,Warehouse_Log!$C$2:$C$4999,$A6,Warehouse_Log!$B$2:$B$4999,"IN",Warehouse_Log!$K$2:$K$4999,"No"),0)) | K6: =IF($E6=0,"Stock only",IF(AND($H6<>"",$H6<=TODAY()),"ORDER NOW",IF(AND($I6>0,IFERROR(_xlfn.MINIFS(Warehouse_Log!$J$2:$J$4999,Warehouse_Log!$C$2:$C$4999,$A6,Warehouse_Log!$B$2:$B$4999,"IN",Warehouse_Log!$K$2:$K$4999,"No"),0)<>0,IFERROR(_xlfn.MINIFS(Warehouse_Log!$J$2:$J$4999,Warehouse_Log!$C$2:$C$4999,$A6,Warehouse_Log!$B$2:$B$4999,"IN",Warehouse_Log!$K$2:$K$4999,"No"),0)<=$G6),"Covered - arriving "&TEXT(IFERROR(_xlfn.MINIFS(Warehouse_Log!$J$2:$J$4999,Warehouse_Log!$C$2:$C$4999,$A6,Warehouse_Log!$B$2:$B$4999,"IN",Warehouse_Log!$K$2:$K$4999,"No"),0),"mmm dd"),IF(AND($H6<>"",($H6-TODAY())<=7),"Order soon","OK")))) -> Stock only
A7: =Setup!$A$16 -> Distilled Water | B7: =SUMIFS(Warehouse_Log!$F$2:$F$4999,Warehouse_Log!$C$2:$C$4999,$A7,Warehouse_Log!$B$2:$B$4999,"IN",Warehouse_Log!$K$2:$K$4999,"<>No")-SUMIFS(Warehouse_Log!$F$2:$F$4999,Warehouse_Log!$C$2:$C$4999,$A7,Warehouse_Log!$B$2:$B$4999,"OUT") -> 35 | C7: =SUMIF(Tank_Levels!$B$2:$B$41,$A7,Tank_Levels!$I$2:$I$41) -> 0 | D7: =$B7+$C7 -> 35 | E7: =SUMIF(Tank_Levels!$B$2:$B$41,$A7,Tank_Levels!$D$2:$D$41) -> 0 | F7: =IF($E7=0,"",$D7/$E7) | G7: =IF($F7="","",TODAY()+$F7) | H7: =IF($G7="","",$G7-Setup!$C$16) | I7: =SUMIFS(Warehouse_Log!$F$2:$F$4999,Warehouse_Log!$C$2:$C$4999,$A7,Warehouse_Log!$B$2:$B$4999,"IN",Warehouse_Log!$K$2:$K$4999,"No") -> 0 | J7: =IF(IFERROR(_xlfn.MINIFS(Warehouse_Log!$J$2:$J$4999,Warehouse_Log!$C$2:$C$4999,$A7,Warehouse_Log!$B$2:$B$4999,"IN",Warehouse_Log!$K$2:$K$4999,"No"),0)=0,"",IFERROR(_xlfn.MINIFS(Warehouse_Log!$J$2:$J$4999,Warehouse_Log!$C$2:$C$4999,$A7,Warehouse_Log!$B$2:$B$4999,"IN",Warehouse_Log!$K$2:$K$4999,"No"),0)) | K7: =IF($E7=0,"Stock only",IF(AND($H7<>"",$H7<=TODAY()),"ORDER NOW",IF(AND($I7>0,IFERROR(_xlfn.MINIFS(Warehouse_Log!$J$2:$J$4999,Warehouse_Log!$C$2:$C$4999,$A7,Warehouse_Log!$B$2:$B$4999,"IN",Warehouse_Log!$K$2:$K$4999,"No"),0)<>0,IFERROR(_xlfn.MINIFS(Warehouse_Log!$J$2:$J$4999,Warehouse_Log!$C$2:$C$4999,$A7,Warehouse_Log!$B$2:$B$4999,"IN",Warehouse_Log!$K$2:$K$4999,"No"),0)<=$G7),"Covered - arriving "&TEXT(IFERROR(_xlfn.MINIFS(Warehouse_Log!$J$2:$J$4999,Warehouse_Log!$C$2:$C$4999,$A7,Warehouse_Log!$B$2:$B$4999,"IN",Warehouse_Log!$K$2:$K$4999,"No"),0),"mmm dd"),IF(AND($H7<>"",($H7-TODAY())<=7),"Order soon","OK")))) -> Stock only
A8: =Setup!$A$17 -> Methanol | B8: =SUMIFS(Warehouse_Log!$F$2:$F$4999,Warehouse_Log!$C$2:$C$4999,$A8,Warehouse_Log!$B$2:$B$4999,"IN",Warehouse_Log!$K$2:$K$4999,"<>No")-SUMIFS(Warehouse_Log!$F$2:$F$4999,Warehouse_Log!$C$2:$C$4999,$A8,Warehouse_Log!$B$2:$B$4999,"OUT") -> 37.5 | C8: =SUMIF(Tank_Levels!$B$2:$B$41,$A8,Tank_Levels!$I$2:$I$41) -> 0 | D8: =$B8+$C8 -> 37.5 | E8: =SUMIF(Tank_Levels!$B$2:$B$41,$A8,Tank_Levels!$D$2:$D$41) -> 0 | F8: =IF($E8=0,"",$D8/$E8) | G8: =IF($F8="","",TODAY()+$F8) | H8: =IF($G8="","",$G8-Setup!$C$17) | I8: =SUMIFS(Warehouse_Log!$F$2:$F$4999,Warehouse_Log!$C$2:$C$4999,$A8,Warehouse_Log!$B$2:$B$4999,"IN",Warehouse_Log!$K$2:$K$4999,"No") -> 0 | J8: =IF(IFERROR(_xlfn.MINIFS(Warehouse_Log!$J$2:$J$4999,Warehouse_Log!$C$2:$C$4999,$A8,Warehouse_Log!$B$2:$B$4999,"IN",Warehouse_Log!$K$2:$K$4999,"No"),0)=0,"",IFERROR(_xlfn.MINIFS(Warehouse_Log!$J$2:$J$4999,Warehouse_Log!$C$2:$C$4999,$A8,Warehouse_Log!$B$2:$B$4999,"IN",Warehouse_Log!$K$2:$K$4999,"No"),0)) | K8: =IF($E8=0,"Stock only",IF(AND($H8<>"",$H8<=TODAY()),"ORDER NOW",IF(AND($I8>0,IFERROR(_xlfn.MINIFS(Warehouse_Log!$J$2:$J$4999,Warehouse_Log!$C$2:$C$4999,$A8,Warehouse_Log!$B$2:$B$4999,"IN",Warehouse_Log!$K$2:$K$4999,"No"),0)<>0,IFERROR(_xlfn.MINIFS(Warehouse_Log!$J$2:$J$4999,Warehouse_Log!$C$2:$C$4999,$A8,Warehouse_Log!$B$2:$B$4999,"IN",Warehouse_Log!$K$2:$K$4999,"No"),0)<=$G8),"Covered - arriving "&TEXT(IFERROR(_xlfn.MINIFS(Warehouse_Log!$J$2:$J$4999,Warehouse_Log!$C$2:$C$4999,$A8,Warehouse_Log!$B$2:$B$4999,"IN",Warehouse_Log!$K$2:$K$4999,"No"),0),"mmm dd"),IF(AND($H8<>"",($H8-TODAY())<=7),"Order soon","OK")))) -> Stock only
A9: =Setup!$A$18 -> Propan-2-ol | B9: =SUMIFS(Warehouse_Log!$F$2:$F$4999,Warehouse_Log!$C$2:$C$4999,$A9,Warehouse_Log!$B$2:$B$4999,"IN",Warehouse_Log!$K$2:$K$4999,"<>No")-SUMIFS(Warehouse_Log!$F$2:$F$4999,Warehouse_Log!$C$2:$C$4999,$A9,Warehouse_Log!$B$2:$B$4999,"OUT") -> 57.5 | C9: =SUMIF(Tank_Levels!$B$2:$B$41,$A9,Tank_Levels!$I$2:$I$41) -> 0 | D9: =$B9+$C9 -> 57.5 | E9: =SUMIF(Tank_Levels!$B$2:$B$41,$A9,Tank_Levels!$D$2:$D$41) -> 0 | F9: =IF($E9=0,"",$D9/$E9) | G9: =IF($F9="","",TODAY()+$F9) | H9: =IF($G9="","",$G9-Setup!$C$18) | I9: =SUMIFS(Warehouse_Log!$F$2:$F$4999,Warehouse_Log!$C$2:$C$4999,$A9,Warehouse_Log!$B$2:$B$4999,"IN",Warehouse_Log!$K$2:$K$4999,"No") -> 0 | J9: =IF(IFERROR(_xlfn.MINIFS(Warehouse_Log!$J$2:$J$4999,Warehouse_Log!$C$2:$C$4999,$A9,Warehouse_Log!$B$2:$B$4999,"IN",Warehouse_Log!$K$2:$K$4999,"No"),0)=0,"",IFERROR(_xlfn.MINIFS(Warehouse_Log!$J$2:$J$4999,Warehouse_Log!$C$2:$C$4999,$A9,Warehouse_Log!$B$2:$B$4999,"IN",Warehouse_Log!$K$2:$K$4999,"No"),0)) | K9: =IF($E9=0,"Stock only",IF(AND($H9<>"",$H9<=TODAY()),"ORDER NOW",IF(AND($I9>0,IFERROR(_xlfn.MINIFS(Warehouse_Log!$J$2:$J$4999,Warehouse_Log!$C$2:$C$4999,$A9,Warehouse_Log!$B$2:$B$4999,"IN",Warehouse_Log!$K$2:$K$4999,"No"),0)<>0,IFERROR(_xlfn.MINIFS(Warehouse_Log!$J$2:$J$4999,Warehouse_Log!$C$2:$C$4999,$A9,Warehouse_Log!$B$2:$B$4999,"IN",Warehouse_Log!$K$2:$K$4999,"No"),0)<=$G9),"Covered - arriving "&TEXT(IFERROR(_xlfn.MINIFS(Warehouse_Log!$J$2:$J$4999,Warehouse_Log!$C$2:$C$4999,$A9,Warehouse_Log!$B$2:$B$4999,"IN",Warehouse_Log!$K$2:$K$4999,"No"),0),"mmm dd"),IF(AND($H9<>"",($H9-TODAY())<=7),"Order soon","OK")))) -> Stock only
A10: =Setup!$A$19 -> Ammonia 30% | B10: =SUMIFS(Warehouse_Log!$F$2:$F$4999,Warehouse_Log!$C$2:$C$4999,$A10,Warehouse_Log!$B$2:$B$4999,"IN",Warehouse_Log!$K$2:$K$4999,"<>No")-SUMIFS(Warehouse_Log!$F$2:$F$4999,Warehouse_Log!$C$2:$C$4999,$A10,Warehouse_Log!$B$2:$B$4999,"OUT") -> 5 | C10: =SUMIF(Tank_Levels!$B$2:$B$41,$A10,Tank_Levels!$I$2:$I$41) -> 0 | D10: =$B10+$C10 -> 5 | E10: =SUMIF(Tank_Levels!$B$2:$B$41,$A10,Tank_Levels!$D$2:$D$41) -> 0 | F10: =IF($E10=0,"",$D10/$E10) | G10: =IF($F10="","",TODAY()+$F10) | H10: =IF($G10="","",$G10-Setup!$C$19) | I10: =SUMIFS(Warehouse_Log!$F$2:$F$4999,Warehouse_Log!$C$2:$C$4999,$A10,Warehouse_Log!$B$2:$B$4999,"IN",Warehouse_Log!$K$2:$K$4999,"No") -> 0 | J10: =IF(IFERROR(_xlfn.MINIFS(Warehouse_Log!$J$2:$J$4999,Warehouse_Log!$C$2:$C$4999,$A10,Warehouse_Log!$B$2:$B$4999,"IN",Warehouse_Log!$K$2:$K$4999,"No"),0)=0,"",IFERROR(_xlfn.MINIFS(Warehouse_Log!$J$2:$J$4999,Warehouse_Log!$C$2:$C$4999,$A10,Warehouse_Log!$B$2:$B$4999,"IN",Warehouse_Log!$K$2:$K$4999,"No"),0)) | K10: =IF($E10=0,"Stock only",IF(AND($H10<>"",$H10<=TODAY()),"ORDER NOW",IF(AND($I10>0,IFERROR(_xlfn.MINIFS(Warehouse_Log!$J$2:$J$4999,Warehouse_Log!$C$2:$C$4999,$A10,Warehouse_Log!$B$2:$B$4999,"IN",Warehouse_Log!$K$2:$K$4999,"No"),0)<>0,IFERROR(_xlfn.MINIFS(Warehouse_Log!$J$2:$J$4999,Warehouse_Log!$C$2:$C$4999,$A10,Warehouse_Log!$B$2:$B$4999,"IN",Warehouse_Log!$K$2:$K$4999,"No"),0)<=$G10),"Covered - arriving "&TEXT(IFERROR(_xlfn.MINIFS(Warehouse_Log!$J$2:$J$4999,Warehouse_Log!$C$2:$C$4999,$A10,Warehouse_Log!$B$2:$B$4999,"IN",Warehouse_Log!$K$2:$K$4999,"No"),0),"mmm dd"),IF(AND($H10<>"",($H10-TODAY())<=7),"Order soon","OK")))) -> Stock only

Sheet Setup
A1: Chemicals
A2: Chemical Name | B2: Category | C2: Reorder Lead Time (days) | D2: Min Stock Threshold (L) | E2: Notes | F2: Default Unit
A3: Demulsifier (89067) | B3: Process Chemicals | C3: 21 | D3: 0 | F3: Drum
A4: Anti-Foam (DF-9000) | B4: Process Chemicals | C4: 21 | D4: 0 | F4: Drum
A5: Scale Inhibitor (SI-44108) | B5: Process Chemicals | C5: 21 | D5: 0 | F5: Drum
A6: Paraffin Inhibitor PI-75135 | B6: Process Chemicals | C6: 21 | D6: 0 | F6: Drum
A7: Paraffin WI-301 | B7: Process Chemicals | C7: 21 | D7: 0 | F7: Drum
A8: Biocide (MB-5207) | B8: Process Chemicals | C8: 21 | D8: 0 | F8: Drum
A9: Corrosion Inhibitor (KI-34154) | B9: Process Chemicals | C9: 21 | D9: 0 | F9: Drum
A10: Flocculant | B10: Process Chemicals | C10: 21 | D10: 0 | F10: Drum
A11: HCl 33% | B11: Boiler Chemicals | C11: 0 | D11: 0 | F11: Liters
A12: Industrial Salt | B12: Boiler Chemicals | C12: 0 | D12: 0 | F12: Bag
A13: N-Hexane | B13: Lab Chemicals | C13: 0 | D13: 0 | F13: Bottle
A14: 1-Butanol | B14: Lab Chemicals | C14: 0 | D14: 0 | F14: Bottle
... A19: Ammonia 30% | B19: Lab Chemicals | C19: 0 | D19: 0 | F19: Bottle
A25: Units — one row per container type actually used (sizes vary by chemical)
A26: Unit Name | B26: Liters per Unit (TBD = fill in)
A27: Liters | B27: 1
A28: Drum | B28: 200
A29: Bag | B29: 2.5
A30: Bottle | B30: 2.5
A45: EPF Skids (production facility)
A46: Skid / Tank Name | B46: Current Chemical | C46: Capacity (L)
A47: Inlet Skid - DE-MULSIFIER (40-Z-01) | C47: 750
A48: Inlet Skid - POUR POINT DEPROSSOR (40-Z-05) | B48: Demulsifier (89067) | C48: 1510
A49: Inlet Skid - CORROSION INHIBITOR (40-Z-09) | B49: Corrosion Inhibitor (KI-34154) | C49: 750
A50: Inlet Skid - SCALE INHIBITOR (40-Z-03) | B50: Scale Inhibitor (SI-44108) | C50: 750
A51: Inlet Skid - ANTIFOAM (40-Z-04) | B51: Anti-Foam (DF-9000) | C51: 750
A52: Water Treatment Skid - CORROSION INHIBITOR (40-Z-08) | B52: Corrosion Inhibitor (KI-34154) | C52: 750
A53: Water Treatment Skid - FLOCCULANT (40-Z-06) | B53: Flocculant | C53: 750
A58: Well Skids
A59: Skid / Tank Name | B59: Current Chemical | C59: Capacity (L) | E59: 30
A60: A-07 Corrosion Inhibitor Skid | B60: Corrosion Inhibitor (KI-34154) | C60: 750
A61: A-07 Biocide Skid | B61: Biocide (MB-5207) | C61: 750
A62: A-131 Scale-Inhibitor Skid | B62: Scale Inhibitor (SI-44108) | C62: 750
A63: A-126 Corrosion Inhibitor Skid | B63: Corrosion Inhibitor (KI-34154) | C63: 750
A64: A-113 Corrosion Inhibitor Skid | B64: Corrosion Inhibitor (KI-34154) | C64: 750
A65: A-131 Corrosion Inhibitor Skid | B65: Corrosion Inhibitor (KI-34154) | C65: 750
A66: A-138 Corrosion Inhibitor Skid | B66: Corrosion Inhibitor (KI-34154) | C66: 750
A67: A-133 Biocide Skid | B67: Biocide (MB-5207) | C67: 750
...

Sheet Warehouse_Log
A1: Date & Time | B1: Type | C1: Chemical | D1: Quantity | E1: Unit | F1: Qty in Liters | G1: Tank / Location (OUT only) | H1: PO Number (IN only) | I1: Supplier (IN only) | J1: Expected/ETA (IN only) | K1: Received? (IN only) | L1: Date Received (IN only) | M1: Notes
A2: 46278 | B2: IN | C2: Demulsifier (89067) | D2: 49 | E2: Drum | F2: =IF(OR($D2="",$E2=""),"",IFERROR($D2*INDEX(Setup!$B$27:$B$44,MATCH($E2,Setup!$A$27:$A$44,0)),"TBD")) -> 9800 | M2: Opening stock count
A3: 46278 | B3: IN | C3: Anti-Foam (DF-9000) | D3: 6 | E3: Drum | F3: =IF(OR($D3="",$E3=""),"",IFERROR($D3*INDEX(Setup!$B$27:$B$44,MATCH($E3,Setup!$A$27:$A$44,0)),"TBD")) -> 1200 | M3: Opening stock count
A4: 46278 | B4: IN | C4: Scale Inhibitor (SI-44108) | D4: 8 | E4: Drum | F4: =IF(OR($D4="",$E4=""),"",IFERROR($D4*INDEX(Setup!$B$27:$B$44,MATCH($E4,Setup!$A$27:$A$44,0)),"TBD")) -> 1600 | M4: Opening stock count
A5: 46278 | B5: IN | C5: Paraffin Inhibitor PI-75135 | D5: 40 | E5: Drum | F5: =IF(OR($D5="",$E5=""),"",IFERROR($D5*INDEX(Setup!$B$27:$B$44,MATCH($E5,Setup!$A$27:$A$44,0)),"TBD")) -> 8000 | M5: Opening stock count
A6: 46278 | B6: IN | C6: Paraffin WI-301 | D6: 4 | E6: Drum | F6: =IF(OR($D6="",$E6=""),"",IFERROR($D6*INDEX(Setup!$B$27:$B$44,MATCH($E6,Setup!$A$27:$A$44,0)),"TBD")) -> 800 | M6: Opening stock count
A7: 46278 | B7: IN | C7: HCl 33% | D7: 720 | E7: Liters | F7: =IF(OR($D7="",$E7=""),"",IFERROR($D7*INDEX(Setup!$B$27:$B$44,MATCH($E7,Setup!$A$27:$A$44,0)),"TBD")) -> 720 | M7: Opening stock count
A8: 46278 | B8: IN | C8: Industrial Salt | D8: 23 | E8: Bag | F8: =IF(OR($D8="",$E8=""),"",IFERROR($D8*INDEX(Setup!$B$27:$B$44,MATCH($E8,Setup!$A$27:$A$44,0)),"TBD")) -> 57.5 | M8: Opening stock count
A9: 46278 | B9: IN | C9: N-Hexane | D9: 4 | E9: Bottle | F9: =IF(OR($D9="",$E9=""),"",IFERROR($D9*INDEX(Setup!$B$27:$B$44,MATCH($E9,Setup!$A$27:$A$44,0)),"TBD")) -> 10 | M9: Opening stock count
A10: 46278 | B10: IN | C10: 1-Butanol | D10: 24 | E10: Bottle | F10: =IF(OR($D10="",$E10=""),"",IFERROR($D10*INDEX(Setup!$B$27:$B$44,MATCH($E10,Setup!$A$27:$A$44,0)),"TBD")) -> 60 | M10: Opening stock count
A11: 46278 | B11: IN | C11: Acetone | D11: 3 | E11: Bottle | F11: =IF(OR($D11="",$E11=""),"",IFERROR($D11*INDEX(Setup!$B$27:$B$44,MATCH($E11,Setup!$A$27:$A$44,0)),"TBD")) -> 7.5 | M11: Opening stock count
A12: 46278 | B12: IN | C12: Distilled Water | D12: 14 | E12: Bottle | F12: =IF(OR($D12="",$E12=""),"",IFERROR($D12*INDEX(Setup!$B$27:$B$44,MATCH($E12,Setup!$A$27:$A$44,0)),"TBD")) -> 35 | M12: Opening stock count
A13: 46278 | B13: IN | C13: Methanol | D13: 15 | E13: Bottle | F13: =IF(OR($D13="",$E13=""),"",IFERROR($D13*INDEX(Setup!$B$27:$B$44,MATCH($E13,Setup!$A$27:$A$44,0)),"TBD")) -> 37.5 | M13: Opening stock count
... A15: 46278 | B15: IN | C15: Ammonia 30% | D15: 2 | E15: Bottle | F15: =IF(OR($D15="",$E15=""),"",IFERROR($D15*INDEX(Setup!$B$27:$B$44,MATCH($E15,Setup!$A$27:$A$44,0)),"TBD")) -> 5 | M15: Opening stock count
A16: 46278 | B16: IN | C16: Biocide (MB-5207) | D16: 4 | E16: Drum | F16: =IF(OR($D16="",$E16=""),"",IFERROR($D16*INDEX(Setup!$B$27:$B$44,MATCH($E16,Setup!$A$27:$A$44,0)),"TBD")) -> 800 | H16: 4801319022 | J16: 46283 | K16: No
A17: 46278 | B17: IN | C17: Corrosion Inhibitor (KI-34154) | D17: 90 | E17: Drum | F17: =IF(OR($D17="",$E17=""),"",IFERROR($D17*INDEX(Setup!$B$27:$B$44,MATCH($E17,Setup!$A$27:$A$44,0)),"TBD")) -> 18000 | H17: 4801325097 | J17: 46283 | K17: No
A18: 46278.417 | B18: OUT | C18: Demulsifier (89067) | D18: 4 | E18: Drum | F18: =IF(OR($D18="",$E18=""),"",IFERROR($D18*INDEX(Setup!$B$27:$B$44,MATCH($E18,Setup!$A$27:$A$44,0)),"TBD")) -> 800 | G18: Inlet Skid - POUR POINT DEPROSSOR (40-Z-05)
A19: 46278.417 | B19: OUT | C19: Scale Inhibitor (SI-44108) | D19: 4 | E19: Drum | F19: =IF(OR($D19="",$E19=""),"",IFERROR($D19*INDEX(Setup!$B$27:$B$44,MATCH($E19,Setup!$A$27:$A$44,0)),"TBD")) -> 800 | G19: Inlet Skid - SCALE INHIBITOR (40-Z-03)
E20: =IF($B20="","",IF($B20="OUT","Liters",IFERROR(INDEX(Setup!$F$3:$F$24,MATCH($C20,Setup!$A$3:$A$24,0)),""))) | F20: =IF(OR($D20="",$E20=""),"",IFERROR($D20*INDEX(Setup!$B$27:$B$44,MATCH($E20,Setup!$A$27:$A$44,0)),"TBD"))
E21: =IF($B21="","",IF($B21="OUT","Liters",IFERROR(INDEX(Setup!$F$3:$F$24,MATCH($C21,Setup!$A$3:$A$24,0)),""))) | F21: =IF(OR($D21="",$E21=""),"",IFERROR($D21*INDEX(Setup!$B$27:$B$44,MATCH($E21,Setup!$A$27:$A$44,0)),"TBD"))
E22: =IF($B22="","",IF($B22="OUT","Liters",IFERROR(INDEX(Setup!$F$3:$F$24,MATCH($C22,Setup!$A$3:$A$24,0)),""))) | F22: =IF(OR($D22="",$E22=""),"",IFERROR($D22*INDEX(Setup!$B$27:$B$44,MATCH($E22,Setup!$A$27:$A$44,0)),"TBD"))
E23: =IF($B23="","",IF($B23="OUT","Liters",IFERROR(INDEX(Setup!$F$3:$F$24,MATCH($C23,Setup!$A$3:$A$24,0)),""))) | F23: =IF(OR($D23="",$E23=""),"",IFERROR($D23*INDEX(Setup!$B$27:$B$44,MATCH($E23,Setup!$A$27:$A$44,0)),"TBD"))
E24: =IF($B24="","",IF($B24="OUT","Liters",IFERROR(INDEX(Setup!$F$3:$F$24,MATCH($C24,Setup!$A$3:$A$24,0)),""))) | F24: =IF(OR($D24="",$E24=""),"",IFERROR($D24*INDEX(Setup!$B$27:$B$44,MATCH($E24,Setup!$A$27:$A$44,0)),"TBD"))
E25: =IF($B25="","",IF($B25="OUT","Liters",IFERROR(INDEX(Setup!$F$3:$F$24,MATCH($C25,Setup!$A$3:$A$24,0)),""))) | F25: =IF(OR($D25="",$E25=""),"",IFERROR($D25*INDEX(Setup!$B$27:$B$44,MATCH($E25,Setup!$A$27:$A$44,0)),"TBD"))
E26: =IF($B26="","",IF($B26="OUT","Liters",IFERROR(INDEX(Setup!$F$3:$F$24,MATCH($C26,Setup!$A$3:$A$24,0)),""))) | F26: =IF(OR($D26="",$E26=""),"",IFERROR($D26*INDEX(Setup!$B$27:$B$44,MATCH($E26,Setup!$A$27:$A$44,0)),"TBD"))
E27: =IF($B27="","",IF($B27="OUT","Liters",IFERROR(INDEX(Setup!$F$3:$F$24,MATCH($C27,Setup!$A$3:$A$24,0)),""))) | F27: =IF(OR($D27="",$E27=""),"",IFERROR($D27*INDEX(Setup!$B$27:$B$44,MATCH($E27,Setup!$A$27:$A$44,0)),"TBD"))
E28: =IF($B28="","",IF($B28="OUT","Liters",IFERROR(INDEX(Setup!$F$3:$F$24,MATCH($C28,Setup!$A$3:$A$24,0)),""))) | F28: =IF(OR($D28="",$E28=""),"",IFERROR($D28*INDEX(Setup!$B$27:$B$44,MATCH($E28,Setup!$A$27:$A$44,0)),"TBD"))
E29: =IF($B29="","",IF($B29="OUT","Liters",IFERROR(INDEX(Setup!$F$3:$F$24,MATCH($C29,Setup!$A$3:$A$24,0)),""))) | F29: =IF(OR($D29="",$E29=""),"",IFERROR($D29*INDEX(Setup!$B$27:$B$44,MATCH($E29,Setup!$A$27:$A$44,0)),"TBD"))
E30: =IF($B30="","",IF($B30="OUT","Liters",IFERROR(INDEX(Setup!$F$3:$F$24,MATCH($C30,Setup!$A$3:$A$24,0)),""))) | F30: =IF(OR($D30="",$E30=""),"",IFERROR($D30*INDEX(Setup!$B$27:$B$44,MATCH($E30,Setup!$A$27:$A$44,0)),"TBD"))
E31: =IF($B31="","",IF($B31="OUT","Liters",IFERROR(INDEX(Setup!$F$3:$F$24,MATCH($C31,Setup!$A$3:$A$24,0)),""))) | F31: =IF(OR($D31="",$E31=""),"",IFERROR($D31*INDEX(Setup!$B$27:$B$44,MATCH($E31,Setup!$A$27:$A$44,0)),"TBD"))
... E4999: =IF($B4999="","",IF($B4999="OUT","Liters",IFERROR(INDEX(Setup!$F$3:$F$24,MATCH($C4999,Setup!$A$3:$A$24,0)),""))) | F4999: =IF(OR($D4999="",$E4999=""),"",IFERROR($D4999*INDEX(Setup!$B$27:$B$44,MATCH($E4999,Setup!$A$27:$A$44,0)),"TBD"))

Sheet Tank_Adjustments
A1: Date & Time | B1: Tank / Skid | C1: Level (%) | D1: Level (Liters) calculated | E1: Reason | F1: Notes
A2: 46278.389 | B2: Inlet Skid - POUR POINT DEPROSSOR (40-Z-05) | C2: 0.28 | D2: =IF(OR($B2="",$C2=""),"",$C2*IFERROR(INDEX(Setup!$C$47:$C$56,MATCH($B2,Setup!$A$47:$A$56,0)),IFERROR(INDEX(Setup!$C$60:$C$89,MATCH($B2,Setup!$A$60:$A$89,0)),""))) -> 422.8 | E2: Manual fill / top-up | F2: Initial Level
A3: 46278.389 | B3: Inlet Skid - CORROSION INHIBITOR (40-Z-09) | C3: 0 | D3: =IF(OR($B3="",$C3=""),"",$C3*IFERROR(INDEX(Setup!$C$47:$C$56,MATCH($B3,Setup!$A$47:$A$56,0)),IFERROR(INDEX(Setup!$C$60:$C$89,MATCH($B3,Setup!$A$60:$A$89,0)),""))) -> 0 | E3: Manual fill / top-up | F3: Initial Level
A4: 46278.389 | B4: Inlet Skid - SCALE INHIBITOR (40-Z-03) | C4: 0 | D4: =IF(OR($B4="",$C4=""),"",$C4*IFERROR(INDEX(Setup!$C$47:$C$56,MATCH($B4,Setup!$A$47:$A$56,0)),IFERROR(INDEX(Setup!$C$60:$C$89,MATCH($B4,Setup!$A$60:$A$89,0)),""))) -> 0 | E4: Manual fill / top-up | F4: Initial Level
A5: 46278.389 | B5: Inlet Skid - ANTIFOAM (40-Z-04) | C5: 0.2 | D5: =IF(OR($B5="",$C5=""),"",$C5*IFERROR(INDEX(Setup!$C$47:$C$56,MATCH($B5,Setup!$A$47:$A$56,0)),IFERROR(INDEX(Setup!$C$60:$C$89,MATCH($B5,Setup!$A$60:$A$89,0)),""))) -> 150 | E5: Manual fill / top-up | F5: Initial Level
A6: 46278.389 | B6: Water Treatment Skid - CORROSION INHIBITOR (40-Z-08) | C6: 0.42 | D6: =IF(OR($B6="",$C6=""),"",$C6*IFERROR(INDEX(Setup!$C$47:$C$56,MATCH($B6,Setup!$A$47:$A$56,0)),IFERROR(INDEX(Setup!$C$60:$C$89,MATCH($B6,Setup!$A$60:$A$89,0)),""))) -> 315 | E6: Manual fill / top-up | F6: Initial Level
A7: 46278.389 | B7: Water Treatment Skid - FLOCCULANT (40-Z-06) | C7: 0.06 | D7: =IF(OR($B7="",$C7=""),"",$C7*IFERROR(INDEX(Setup!$C$47:$C$56,MATCH($B7,Setup!$A$47:$A$56,0)),IFERROR(INDEX(Setup!$C$60:$C$89,MATCH($B7,Setup!$A$60:$A$89,0)),""))) -> 45 | E7: Manual fill / top-up | F7: Initial Level
A8: 46275.688 | B8: A-07 Corrosion Inhibitor Skid | C8: 0.63 | D8: =IF(OR($B8="",$C8=""),"",$C8*IFERROR(INDEX(Setup!$C$47:$C$56,MATCH($B8,Setup!$A$47:$A$56,0)),IFERROR(INDEX(Setup!$C$60:$C$89,MATCH($B8,Setup!$A$60:$A$89,0)),""))) -> 472.5 | E8: Manual fill / top-up | F8: Initial Level
A9: 46275.688 | B9: A-07 Biocide Skid | C9: 0.2 | D9: =IF(OR($B9="",$C9=""),"",$C9*IFERROR(INDEX(Setup!$C$47:$C$56,MATCH($B9,Setup!$A$47:$A$56,0)),IFERROR(INDEX(Setup!$C$60:$C$89,MATCH($B9,Setup!$A$60:$A$89,0)),""))) -> 150 | E9: Manual fill / top-up | F9: Initial Level
A10: 46275.688 | B10: A-131 Scale-Inhibitor Skid | C10: 0.3 | D10: =IF(OR($B10="",$C10=""),"",$C10*IFERROR(INDEX(Setup!$C$47:$C$56,MATCH($B10,Setup!$A$47:$A$56,0)),IFERROR(INDEX(Setup!$C$60:$C$89,MATCH($B10,Setup!$A$60:$A$89,0)),""))) -> 225 | E10: Manual fill / top-up | F10: Initial Level
A11: 46275.688 | B11: A-126 Corrosion Inhibitor Skid | C11: 0.12 | D11: =IF(OR($B11="",$C11=""),"",$C11*IFERROR(INDEX(Setup!$C$47:$C$56,MATCH($B11,Setup!$A$47:$A$56,0)),IFERROR(INDEX(Setup!$C$60:$C$89,MATCH($B11,Setup!$A$60:$A$89,0)),""))) -> 90 | E11: Manual fill / top-up | F11: Initial Level
A12: 46275.688 | B12: A-113 Corrosion Inhibitor Skid | C12: 0.22 | D12: =IF(OR($B12="",$C12=""),"",$C12*IFERROR(INDEX(Setup!$C$47:$C$56,MATCH($B12,Setup!$A$47:$A$56,0)),IFERROR(INDEX(Setup!$C$60:$C$89,MATCH($B12,Setup!$A$60:$A$89,0)),""))) -> 165 | E12: Manual fill / top-up | F12: Initial Level
A13: 46275.688 | B13: A-131 Corrosion Inhibitor Skid | C13: 0.45 | D13: =IF(OR($B13="",$C13=""),"",$C13*IFERROR(INDEX(Setup!$C$47:$C$56,MATCH($B13,Setup!$A$47:$A$56,0)),IFERROR(INDEX(Setup!$C$60:$C$89,MATCH($B13,Setup!$A$60:$A$89,0)),""))) -> 337.5 | E13: Manual fill / top-up | F13: Initial Level
... A18: 46275.688 | B18: A-130 Biocide Skid | C18: 0.06 | D18: =IF(OR($B18="",$C18=""),"",$C18*IFERROR(INDEX(Setup!$C$47:$C$56,MATCH($B18,Setup!$A$47:$A$56,0)),IFERROR(INDEX(Setup!$C$60:$C$89,MATCH($B18,Setup!$A$60:$A$89,0)),""))) -> 45 | E18: Manual fill / top-up | F18: Initial Level
D19: =IF(OR($B19="",$C19=""),"",$C19*IFERROR(INDEX(Setup!$C$47:$C$56,MATCH($B19,Setup!$A$47:$A$56,0)),IFERROR(INDEX(Setup!$C$60:$C$89,MATCH($B19,Setup!$A$60:$A$89,0)),"")))
D20: =IF(OR($B20="",$C20=""),"",$C20*IFERROR(INDEX(Setup!$C$47:$C$56,MATCH($B20,Setup!$A$47:$A$56,0)),IFERROR(INDEX(Setup!$C$60:$C$89,MATCH($B20,Setup!$A$60:$A$89,0)),"")))
D21: =IF(OR($B21="",$C21=""),"",$C21*IFERROR(INDEX(Setup!$C$47:$C$56,MATCH($B21,Setup!$A$47:$A$56,0)),IFERROR(INDEX(Setup!$C$60:$C$89,MATCH($B21,Setup!$A$60:$A$89,0)),"")))
D22: =IF(OR($B22="",$C22=""),"",$C22*IFERROR(INDEX(Setup!$C$47:$C$56,MATCH($B22,Setup!$A$47:$A$56,0)),IFERROR(INDEX(Setup!$C$60:$C$89,MATCH($B22,Setup!$A$60:$A$89,0)),"")))
D23: =IF(OR($B23="",$C23=""),"",$C23*IFERROR(INDEX(Setup!$C$47:$C$56,MATCH($B23,Setup!$A$47:$A$56,0)),IFERROR(INDEX(Setup!$C$60:$C$89,MATCH($B23,Setup!$A$60:$A$89,0)),"")))
D24: =IF(OR($B24="",$C24=""),"",$C24*IFERROR(INDEX(Setup!$C$47:$C$56,MATCH($B24,Setup!$A$47:$A$56,0)),IFERROR(INDEX(Setup!$C$60:$C$89,MATCH($B24,Setup!$A$60:$A$89,0)),"")))
D25: =IF(OR($B25="",$C25=""),"",$C25*IFERROR(INDEX(Setup!$C$47:$C$56,MATCH($B25,Setup!$A$47:$A$56,0)),IFERROR(INDEX(Setup!$C$60:$C$89,MATCH($B25,Setup!$A$60:$A$89,0)),"")))
D26: =IF(OR($B26="",$C26=""),"",$C26*IFERROR(INDEX(Setup!$C$47:$C$56,MATCH($B26,Setup!$A$47:$A$56,0)),IFERROR(INDEX(Setup!$C$60:$C$89,MATCH($B26,Setup!$A$60:$A$89,0)),"")))
D27: =IF(OR($B27="",$C27=""),"",$C27*IFERROR(INDEX(Setup!$C$47:$C$56,MATCH($B27,Setup!$A$47:$A$56,0)),IFERROR(INDEX(Setup!$C$60:$C$89,MATCH($B27,Setup!$A$60:$A$89,0)),"")))
D28: =IF(OR($B28="",$C28=""),"",$C28*IFERROR(INDEX(Setup!$C$47:$C$56,MATCH($B28,Setup!$A$47:$A$56,0)),IFERROR(INDEX(Setup!$C$60:$C$89,MATCH($B28,Setup!$A$60:$A$89,0)),"")))
D29: =IF(OR($B29="",$C29=""),"",$C29*IFERROR(INDEX(Setup!$C$47:$C$56,MATCH($B29,Setup!$A$47:$A$56,0)),IFERROR(INDEX(Setup!$C$60:$C$89,MATCH($B29,Setup!$A$60:$A$89,0)),"")))
D30: =IF(OR($B30="",$C30=""),"",$C30*IFERROR(INDEX(Setup!$C$47:$C$56,MATCH($B30,Setup!$A$47:$A$56,0)),IFERROR(INDEX(Setup!$C$60:$C$89,MATCH($B30,Setup!$A$60:$A$89,0)),"")))
... D4998: =IF(OR($B4998="",$C4998=""),"",$C4998*IFERROR(INDEX(Setup!$C$47:$C$56,MATCH($B4998,Setup!$A$47:$A$56,0)),IFERROR(INDEX(Setup!$C$60:$C$89,MATCH($B4998,Setup!$A$60:$A$89,0)),"")))

Sheet Dosage
A1: Current calculation time (NOW): | B1: =NOW() -> 46279.599
A2: Skid / Tank | B2: Effective From (date & time) | C2: LPH | D2: Duration (hrs/dose) | E2: Frequency (days between doses) | F2: Avg Daily Rate (L/day, calculated) | G2: Notes | H2: Segment End (auto, don't edit)
A3: Inlet Skid - POUR POINT DEPROSSOR (40-Z-05) | B3: 46278.396 | C3: 5 | D3: 24 | E3: 1 | F3: =IF(OR(C3="",D3="",E3="",E3=0),0,C3*D3/E3) -> 120 | G3: Initial rate | H3: =IF(OR($A3="",_xlfn.MINIFS($B$3:$B$5000,$A$3:$A$5000,$A3,$B$3:$B$5000,">"&$B3)=0),NOW(),_xlfn.MINIFS($B$3:$B$5000,$A$3:$A$5000,$A3,$B$3:$B$5000,">"&$B3)) -> 46279.599
A4: Inlet Skid - CORROSION INHIBITOR (40-Z-09) | B4: 46278.396 | C4: 0 | D4: 24 | E4: 1 | F4: =IF(OR(C4="",D4="",E4="",E4=0),0,C4*D4/E4) -> 0 | G4: Initial rate | H4: =IF(OR($A4="",_xlfn.MINIFS($B$3:$B$5000,$A$3:$A$5000,$A4,$B$3:$B$5000,">"&$B4)=0),NOW(),_xlfn.MINIFS($B$3:$B$5000,$A$3:$A$5000,$A4,$B$3:$B$5000,">"&$B4)) -> 46279.599
A5: Inlet Skid - SCALE INHIBITOR (40-Z-03) | B5: 46278.396 | C5: 1 | D5: 24 | E5: 1 | F5: =IF(OR(C5="",D5="",E5="",E5=0),0,C5*D5/E5) -> 24 | G5: Initial rate | H5: =IF(OR($A5="",_xlfn.MINIFS($B$3:$B$5000,$A$3:$A$5000,$A5,$B$3:$B$5000,">"&$B5)=0),NOW(),_xlfn.MINIFS($B$3:$B$5000,$A$3:$A$5000,$A5,$B$3:$B$5000,">"&$B5)) -> 46279.599
A6: Inlet Skid - ANTIFOAM (40-Z-04) | B6: 46278.396 | C6: 0 | D6: 24 | E6: 1 | F6: =IF(OR(C6="",D6="",E6="",E6=0),0,C6*D6/E6) -> 0 | G6: Initial rate | H6: =IF(OR($A6="",_xlfn.MINIFS($B$3:$B$5000,$A$3:$A$5000,$A6,$B$3:$B$5000,">"&$B6)=0),NOW(),_xlfn.MINIFS($B$3:$B$5000,$A$3:$A$5000,$A6,$B$3:$B$5000,">"&$B6)) -> 46279.599
A7: Water Treatment Skid - CORROSION INHIBITOR (40-Z-08) | B7: 46278.396 | C7: 0.35 | D7: 24 | E7: 1 | F7: =IF(OR(C7="",D7="",E7="",E7=0),0,C7*D7/E7) -> 8.4 | G7: Initial rate | H7: =IF(OR($A7="",_xlfn.MINIFS($B$3:$B$5000,$A$3:$A$5000,$A7,$B$3:$B$5000,">"&$B7)=0),NOW(),_xlfn.MINIFS($B$3:$B$5000,$A$3:$A$5000,$A7,$B$3:$B$5000,">"&$B7)) -> 46279.599
A8: Water Treatment Skid - FLOCCULANT (40-Z-06) | B8: 46278.396 | C8: 0.25 | D8: 24 | E8: 1 | F8: =IF(OR(C8="",D8="",E8="",E8=0),0,C8*D8/E8) -> 6 | G8: Initial rate | H8: =IF(OR($A8="",_xlfn.MINIFS($B$3:$B$5000,$A$3:$A$5000,$A8,$B$3:$B$5000,">"&$B8)=0),NOW(),_xlfn.MINIFS($B$3:$B$5000,$A$3:$A$5000,$A8,$B$3:$B$5000,">"&$B8)) -> 46279.599
A9: A-07 Corrosion Inhibitor Skid | B9: 46275.708 | C9: 0.42 | D9: 24 | E9: 1 | F9: =IF(OR(C9="",D9="",E9="",E9=0),0,C9*D9/E9) -> 10.08 | G9: Initial rate | H9: =IF(OR($A9="",_xlfn.MINIFS($B$3:$B$5000,$A$3:$A$5000,$A9,$B$3:$B$5000,">"&$B9)=0),NOW(),_xlfn.MINIFS($B$3:$B$5000,$A$3:$A$5000,$A9,$B$3:$B$5000,">"&$B9)) -> 46279.599
A10: A-07 Biocide Skid | B10: 46275.708 | C10: 0.6 | D10: 5 | E10: 14 | F10: =IF(OR(C10="",D10="",E10="",E10=0),0,C10*D10/E10) -> 0.21428571 | G10: Initial rate | H10: =IF(OR($A10="",_xlfn.MINIFS($B$3:$B$5000,$A$3:$A$5000,$A10,$B$3:$B$5000,">"&$B10)=0),NOW(),_xlfn.MINIFS($B$3:$B$5000,$A$3:$A$5000,$A10,$B$3:$B$5000,">"&$B10)) -> 46279.599
A11: A-131 Scale-Inhibitor Skid | B11: 46275.708 | C11: 0.21 | D11: 24 | E11: 1 | F11: =IF(OR(C11="",D11="",E11="",E11=0),0,C11*D11/E11) -> 5.04 | G11: Initial rate | H11: =IF(OR($A11="",_xlfn.MINIFS($B$3:$B$5000,$A$3:$A$5000,$A11,$B$3:$B$5000,">"&$B11)=0),NOW(),_xlfn.MINIFS($B$3:$B$5000,$A$3:$A$5000,$A11,$B$3:$B$5000,">"&$B11)) -> 46279.599
A12: A-126 Corrosion Inhibitor Skid | B12: 46275.708 | C12: 1.67 | D12: 24 | E12: 1 | F12: =IF(OR(C12="",D12="",E12="",E12=0),0,C12*D12/E12) -> 40.08 | G12: Initial rate | H12: =IF(OR($A12="",_xlfn.MINIFS($B$3:$B$5000,$A$3:$A$5000,$A12,$B$3:$B$5000,">"&$B12)=0),NOW(),_xlfn.MINIFS($B$3:$B$5000,$A$3:$A$5000,$A12,$B$3:$B$5000,">"&$B12)) -> 46279.599
A13: A-113 Corrosion Inhibitor Skid | B13: 46275.708 | C13: 0.95 | D13: 24 | E13: 1 | F13: =IF(OR(C13="",D13="",E13="",E13=0),0,C13*D13/E13) -> 22.8 | G13: Initial rate | H13: =IF(OR($A13="",_xlfn.MINIFS($B$3:$B$5000,$A$3:$A$5000,$A13,$B$3:$B$5000,">"&$B13)=0),NOW(),_xlfn.MINIFS($B$3:$B$5000,$A$3:$A$5000,$A13,$B$3:$B$5000,">"&$B13)) -> 46279.599
A14: A-131 Corrosion Inhibitor Skid | B14: 46275.708 | C14: 0.83333 | D14: 24 | E14: 1 | F14: =IF(OR(C14="",D14="",E14="",E14=0),0,C14*D14/E14) -> 19.99992 | G14: Initial rate | H14: =IF(OR($A14="",_xlfn.MINIFS($B$3:$B$5000,$A$3:$A$5000,$A14,$B$3:$B$5000,">"&$B14)=0),NOW(),_xlfn.MINIFS($B$3:$B$5000,$A$3:$A$5000,$A14,$B$3:$B$5000,">"&$B14)) -> 46279.599
... A19: A-130 Biocide Skid | B19: 46275.708 | C19: 6.2 | D19: 5 | E19: 14 | F19: =IF(OR(C19="",D19="",E19="",E19=0),0,C19*D19/E19) -> 2.2142857 | G19: Initial rate | H19: =IF(OR($A19="",_xlfn.MINIFS($B$3:$B$5000,$A$3:$A$5000,$A19,$B$3:$B$5000,">"&$B19)=0),NOW(),_xlfn.MINIFS($B$3:$B$5000,$A$3:$A$5000,$A19,$B$3:$B$5000,">"&$B19)) -> 46279.599
F20: =IF(OR(C20="",D20="",E20="",E20=0),0,C20*D20/E20) -> 0 | H20: =IF(OR($A20="",_xlfn.MINIFS($B$3:$B$5000,$A$3:$A$5000,$A20,$B$3:$B$5000,">"&$B20)=0),NOW(),_xlfn.MINIFS($B$3:$B$5000,$A$3:$A$5000,$A20,$B$3:$B$5000,">"&$B20)) -> 46279.599
F21: =IF(OR(C21="",D21="",E21="",E21=0),0,C21*D21/E21) -> 0 | H21: =IF(OR($A21="",_xlfn.MINIFS($B$3:$B$5000,$A$3:$A$5000,$A21,$B$3:$B$5000,">"&$B21)=0),NOW(),_xlfn.MINIFS($B$3:$B$5000,$A$3:$A$5000,$A21,$B$3:$B$5000,">"&$B21)) -> 46279.599
F22: =IF(OR(C22="",D22="",E22="",E22=0),0,C22*D22/E22) -> 0 | H22: =IF(OR($A22="",_xlfn.MINIFS($B$3:$B$5000,$A$3:$A$5000,$A22,$B$3:$B$5000,">"&$B22)=0),NOW(),_xlfn.MINIFS($B$3:$B$5000,$A$3:$A$5000,$A22,$B$3:$B$5000,">"&$B22)) -> 46279.599
F23: =IF(OR(C23="",D23="",E23="",E23=0),0,C23*D23/E23) -> 0 | H23: =IF(OR($A23="",_xlfn.MINIFS($B$3:$B$5000,$A$3:$A$5000,$A23,$B$3:$B$5000,">"&$B23)=0),NOW(),_xlfn.MINIFS($B$3:$B$5000,$A$3:$A$5000,$A23,$B$3:$B$5000,">"&$B23)) -> 46279.599
F24: =IF(OR(C24="",D24="",E24="",E24=0),0,C24*D24/E24) -> 0 | H24: =IF(OR($A24="",_xlfn.MINIFS($B$3:$B$5000,$A$3:$A$5000,$A24,$B$3:$B$5000,">"&$B24)=0),NOW(),_xlfn.MINIFS($B$3:$B$5000,$A$3:$A$5000,$A24,$B$3:$B$5000,">"&$B24)) -> 46279.599
F25: =IF(OR(C25="",D25="",E25="",E25=0),0,C25*D25/E25) -> 0 | H25: =IF(OR($A25="",_xlfn.MINIFS($B$3:$B$5000,$A$3:$A$5000,$A25,$B$3:$B$5000,">"&$B25)=0),NOW(),_xlfn.MINIFS($B$3:$B$5000,$A$3:$A$5000,$A25,$B$3:$B$5000,">"&$B25)) -> 46279.599
F26: =IF(OR(C26="",D26="",E26="",E26=0),0,C26*D26/E26) -> 0 | H26: =IF(OR($A26="",_xlfn.MINIFS($B$3:$B$5000,$A$3:$A$5000,$A26,$B$3:$B$5000,">"&$B26)=0),NOW(),_xlfn.MINIFS($B$3:$B$5000,$A$3:$A$5000,$A26,$B$3:$B$5000,">"&$B26)) -> 46279.599
F27: =IF(OR(C27="",D27="",E27="",E27=0),0,C27*D27/E27) -> 0 | H27: =IF(OR($A27="",_xlfn.MINIFS($B$3:$B$5000,$A$3:$A$5000,$A27,$B$3:$B$5000,">"&$B27)=0),NOW(),_xlfn.MINIFS($B$3:$B$5000,$A$3:$A$5000,$A27,$B$3:$B$5000,">"&$B27)) -> 46279.599
F28: =IF(OR(C28="",D28="",E28="",E28=0),0,C28*D28/E28) -> 0 | H28: =IF(OR($A28="",_xlfn.MINIFS($B$3:$B$5000,$A$3:$A$5000,$A28,$B$3:$B$5000,">"&$B28)=0),NOW(),_xlfn.MINIFS($B$3:$B$5000,$A$3:$A$5000,$A28,$B$3:$B$5000,">"&$B28)) -> 46279.599
F29: =IF(OR(C29="",D29="",E29="",E29=0),0,C29*D29/E29) -> 0 | H29: =IF(OR($A29="",_xlfn.MINIFS($B$3:$B$5000,$A$3:$A$5000,$A29,$B$3:$B$5000,">"&$B29)=0),NOW(),_xlfn.MINIFS($B$3:$B$5000,$A$3:$A$5000,$A29,$B$3:$B$5000,">"&$B29)) -> 46279.599
F30: =IF(OR(C30="",D30="",E30="",E30=0),0,C30*D30/E30) -> 0 | H30: =IF(OR($A30="",_xlfn.MINIFS($B$3:$B$5000,$A$3:$A$5000,$A30,$B$3:$B$5000,">"&$B30)=0),NOW(),_xlfn.MINIFS($B$3:$B$5000,$A$3:$A$5000,$A30,$B$3:$B$5000,">"&$B30)) -> 46279.599
F31: =IF(OR(C31="",D31="",E31="",E31=0),0,C31*D31/E31) -> 0 | H31: =IF(OR($A31="",_xlfn.MINIFS($B$3:$B$5000,$A$3:$A$5000,$A31,$B$3:$B$5000,">"&$B31)=0),NOW(),_xlfn.MINIFS($B$3:$B$5000,$A$3:$A$5000,$A31,$B$3:$B$5000,">"&$B31)) -> 46279.599
... F62: =IF(OR(C62="",D62="",E62="",E62=0),0,C62*D62/E62) -> 0 | H62: =IF(OR($A62="",_xlfn.MINIFS($B$3:$B$5000,$A$3:$A$5000,$A62,$B$3:$B$5000,">"&$B62)=0),NOW(),_xlfn.MINIFS($B$3:$B$5000,$A$3:$A$5000,$A62,$B$3:$B$5000,">"&$B62)) -> 46279.599
A63: Well A-07 Corrosion Inhibitor | F63: =IF(OR(C63="",D63="",E63="",E63=0),0,C63*D63/E63) -> 0 | H63: =IF(OR($A63="",_xlfn.MINIFS($B$3:$B$5000,$A$3:$A$5000,$A63,$B$3:$B$5000,">"&$B63)=0),NOW(),_xlfn.MINIFS($B$3:$B$5000,$A$3:$A$5000,$A63,$B$3:$B$5000,">"&$B63)) -> 46279.599
A64: xsxcs | F64: =IF(OR(C64="",D64="",E64="",E64=0),0,C64*D64/E64) -> 0 | H64: =IF(OR($A64="",_xlfn.MINIFS($B$3:$B$5000,$A$3:$A$5000,$A64,$B$3:$B$5000,">"&$B64)=0),NOW(),_xlfn.MINIFS($B$3:$B$5000,$A$3:$A$5000,$A64,$B$3:$B$5000,">"&$B64)) -> 46279.599
A65: Well A-113 | F65: =IF(OR(C65="",D65="",E65="",E65=0),0,C65*D65/E65) -> 0 | H65: =IF(OR($A65="",_xlfn.MINIFS($B$3:$B$5000,$A$3:$A$5000,$A65,$B$3:$B$5000,">"&$B65)=0),NOW(),_xlfn.MINIFS($B$3:$B$5000,$A$3:$A$5000,$A65,$B$3:$B$5000,">"&$B65)) -> 46279.599
F66: =IF(OR(C66="",D66="",E66="",E66=0),0,C66*D66/E66) -> 0 | H66: =IF(OR($A66="",_xlfn.MINIFS($B$3:$B$5000,$A$3:$A$5000,$A66,$B$3:$B$5000,">"&$B66)=0),NOW(),_xlfn.MINIFS($B$3:$B$5000,$A$3:$A$5000,$A66,$B$3:$B$5000,">"&$B66)) -> 46279.599
F67: =IF(OR(C67="",D67="",E67="",E67=0),0,C67*D67/E67) -> 0 | H67: =IF(OR($A67="",_xlfn.MINIFS($B$3:$B$5000,$A$3:$A$5000,$A67,$B$3:$B$5000,">"&$B67)=0),NOW(),_xlfn.MINIFS($B$3:$B$5000,$A$3:$A$5000,$A67,$B$3:$B$5000,">"&$B67)) -> 46279.599
F68: =IF(OR(C68="",D68="",E68="",E68=0),0,C68*D68/E68) -> 0 | H68: =IF(OR($A68="",_xlfn.MINIFS($B$3:$B$5000,$A$3:$A$5000,$A68,$B$3:$B$5000,">"&$B68)=0),NOW(),_xlfn.MINIFS($B$3:$B$5000,$A$3:$A$5000,$A68,$B$3:$B$5000,">"&$B68)) -> 46279.599
F69: =IF(OR(C69="",D69="",E69="",E69=0),0,C69*D69/E69) -> 0 | H69: =IF(OR($A69="",_xlfn.MINIFS($B$3:$B$5000,$A$3:$A$5000,$A69,$B$3:$B$5000,">"&$B69)=0),NOW(),_xlfn.MINIFS($B$3:$B$5000,$A$3:$A$5000,$A69,$B$3:$B$5000,">"&$B69)) -> 46279.599
F70: =IF(OR(C70="",D70="",E70="",E70=0),0,C70*D70/E70) -> 0 | H70: =IF(OR($A70="",_xlfn.MINIFS($B$3:$B$5000,$A$3:$A$5000,$A70,$B$3:$B$5000,">"&$B70)=0),NOW(),_xlfn.MINIFS($B$3:$B$5000,$A$3:$A$5000,$A70,$B$3:$B$5000,">"&$B70)) -> 46279.599
F71: =IF(OR(C71="",D71="",E71="",E71=0),0,C71*D71/E71) -> 0 | H71: =IF(OR($A71="",_xlfn.MINIFS($B$3:$B$5000,$A$3:$A$5000,$A71,$B$3:$B$5000,">"&$B71)=0),NOW(),_xlfn.MINIFS($B$3:$B$5000,$A$3:$A$5000,$A71,$B$3:$B$5000,">"&$B71)) -> 46279.599
F72: =IF(OR(C72="",D72="",E72="",E72=0),0,C72*D72/E72) -> 0 | H72: =IF(OR($A72="",_xlfn.MINIFS($B$3:$B$5000,$A$3:$A$5000,$A72,$B$3:$B$5000,">"&$B72)=0),NOW(),_xlfn.MINIFS($B$3:$B$5000,$A$3:$A$5000,$A72,$B$3:$B$5000,">"&$B72)) -> 46279.599
F73: =IF(OR(C73="",D73="",E73="",E73=0),0,C73*D73/E73) -> 0 | H73: =IF(OR($A73="",_xlfn.MINIFS($B$3:$B$5000,$A$3:$A$5000,$A73,$B$3:$B$5000,">"&$B73)=0),NOW(),_xlfn.MINIFS($B$3:$B$5000,$A$3:$A$5000,$A73,$B$3:$B$5000,">"&$B73)) -> 46279.599
F74: =IF(OR(C74="",D74="",E74="",E74=0),0,C74*D74/E74) -> 0 | H74: =IF(OR($A74="",_xlfn.MINIFS($B$3:$B$5000,$A$3:$A$5000,$A74,$B$3:$B$5000,">"&$B74)=0),NOW(),_xlfn.MINIFS($B$3:$B$5000,$A$3:$A$5000,$A74,$B$3:$B$5000,">"&$B74)) -> 46279.599
...

Sheet Tank_Levels
A1: Skid / Tank | B1: Current Chemical | C1: Capacity (L) | D1: Current Rate (L/day) | E1: Last Reading (date & time) | F1: Level at Reading (L) | G1: Fills Since Reading (L) | H1: Consumed Since Reading (L) | I1: Current Level (L) | J1: Current % | K1: Days to Empty | L1: Projected Empty Date | N1: Filled % | O1: Empty %
A2: =Setup!$A$92 -> Inlet Skid - DE-MULSIFIER (40-Z-01) | B2: =IF(Setup!$A$92="","",IFERROR(INDEX(Setup!$B$47:$B$89,MATCH(Setup!$A$92,Setup!$A$47:$A$89,0)),"")) -> 0 | C2: =IF(Setup!$A$92="","",IFERROR(INDEX(Setup!$C$47:$C$89,MATCH(Setup!$A$92,Setup!$A$47:$A$89,0)),"")) -> 750 | D2: =IF($A2="","",SUMPRODUCT((Dosage!$A$3:$A$5000=$A2)*(Dosage!$B$3:$B$5000=_xlfn.MAXIFS(Dosage!$B$3:$B$5000,Dosage!$A$3:$A$5000,$A2,Dosage!$B$3:$B$5000,"<="&NOW()))*Dosage!$F$3:$F$5000)) -> 0 | E2: =IF($A2="","",IF(COUNTIFS(Tank_Adjustments!$B$2:$B$4998,$A2)>0,_xlfn.MAXIFS(Tank_Adjustments!$A$2:$A$4998,Tank_Adjustments!$B$2:$B$4998,$A2),IF(COUNTIFS(Warehouse_Log!$G$2:$G$4999,$A2,Warehouse_Log!$B$2:$B$4999,"OUT")>0,_xlfn.MINIFS(Warehouse_Log!$A$2:$A$4999,Warehouse_Log!$G$2:$G$4999,$A2,Warehouse_Log!$B$2:$B$4999,"OUT"),""))) | F2: =IF(OR($A2="",$E2=""),0,IF(COUNTIFS(Tank_Adjustments!$B$2:$B$4998,$A2)>0,SUMIFS(Tank_Adjustments!$D$2:$D$4998,Tank_Adjustments!$B$2:$B$4998,$A2,Tank_Adjustments!$A$2:$A$4998,$E2),0)) -> 0 | G2: =IF(OR($A2="",$E2=""),0,IF(COUNTIFS(Tank_Adjustments!$B$2:$B$4998,$A2)>0,SUMIFS(Warehouse_Log!$F$2:$F$4999,Warehouse_Log!$G$2:$G$4999,$A2,Warehouse_Log!$B$2:$B$4999,"OUT",Warehouse_Log!$A$2:$A$4999,">"&$E2),SUMIFS(Warehouse_Log!$F$2:$F$4999,Warehouse_Log!$G$2:$G$4999,$A2,Warehouse_Log!$B$2:$B$4999,"OUT",Warehouse_Log!$A$2:$A$4999,">="&$E2))) -> 0 | H2: =IF(OR($A2="",$E2=""),0,SUMPRODUCT((Dosage!$A$3:$A$5000=$A2)*(((Dosage!$H$3:$H$5000*(Dosage!$H$3:$H$5000<=NOW())+NOW()*(Dosage!$H$3:$H$5000>NOW()))-(Dosage!$B$3:$B$5000*(Dosage!$B$3:$B$5000>=$E2)+$E2*(Dosage!$B$3:$B$5000<$E2)))>0)*((Dosage!$H$3:$H$5000*(Dosage!$H$3:$H$5000<=NOW())+NOW()*(Dosage!$H$3:$H$5000>NOW()))-(Dosage!$B$3:$B$5000*(Dosage!$B$3:$B$5000>=$E2)+$E2*(Dosage!$B$3:$B$5000<$E2)))*Dosage!$F$3:$F$5000)) -> 0 | I2: =IF(OR($A2="",$E2=""),"",MIN($C2,MAX(0,$F2+$G2-$H2))) | J2: =IF(OR($I2="",$C2="",$C2=0),"",$I2/$C2) | K2: =IF(OR($I2="",$D2="",$D2=0),"",$I2/$D2) | L2: =IF($K2="","",TODAY()+$K2) | N2: =IF($J2="","",MIN(1,$J2)) | O2: =IF($J2="","",MAX(0,1-$J2))
A3: =Setup!$A$93 -> Inlet Skid - POUR POINT DEPROSSOR (40-Z-05) | B3: =IF(Setup!$A$93="","",IFERROR(INDEX(Setup!$B$47:$B$89,MATCH(Setup!$A$93,Setup!$A$47:$A$89,0)),"")) -> Demulsifier (89067) | C3: =IF(Setup!$A$93="","",IFERROR(INDEX(Setup!$C$47:$C$89,MATCH(Setup!$A$93,Setup!$A$47:$A$89,0)),"")) -> 1510 | D3: =IF($A3="","",SUMPRODUCT((Dosage!$A$3:$A$5000=$A3)*(Dosage!$B$3:$B$5000=_xlfn.MAXIFS(Dosage!$B$3:$B$5000,Dosage!$A$3:$A$5000,$A3,Dosage!$B$3:$B$5000,"<="&NOW()))*Dosage!$F$3:$F$5000)) -> 120 | E3: =IF($A3="","",IF(COUNTIFS(Tank_Adjustments!$B$2:$B$4998,$A3)>0,_xlfn.MAXIFS(Tank_Adjustments!$A$2:$A$4998,Tank_Adjustments!$B$2:$B$4998,$A3),IF(COUNTIFS(Warehouse_Log!$G$2:$G$4999,$A3,Warehouse_Log!$B$2:$B$4999,"OUT")>0,_xlfn.MINIFS(Warehouse_Log!$A$2:$A$4999,Warehouse_Log!$G$2:$G$4999,$A3,Warehouse_Log!$B$2:$B$4999,"OUT"),""))) -> 46278.389 | F3: =IF(OR($A3="",$E3=""),0,IF(COUNTIFS(Tank_Adjustments!$B$2:$B$4998,$A3)>0,SUMIFS(Tank_Adjustments!$D$2:$D$4998,Tank_Adjustments!$B$2:$B$4998,$A3,Tank_Adjustments!$A$2:$A$4998,$E3),0)) -> 422.8 | G3: =IF(OR($A3="",$E3=""),0,IF(COUNTIFS(Tank_Adjustments!$B$2:$B$4998,$A3)>0,SUMIFS(Warehouse_Log!$F$2:$F$4999,Warehouse_Log!$G$2:$G$4999,$A3,Warehouse_Log!$B$2:$B$4999,"OUT",Warehouse_Log!$A$2:$A$4999,">"&$E3),SUMIFS(Warehouse_Log!$F$2:$F$4999,Warehouse_Log!$G$2:$G$4999,$A3,Warehouse_Log!$B$2:$B$4999,"OUT",Warehouse_Log!$A$2:$A$4999,">="&$E3))) -> 800 | H3: =IF(OR($A3="",$E3=""),0,SUMPRODUCT((Dosage!$A$3:$A$5000=$A3)*(((Dosage!$H$3:$H$5000*(Dosage!$H$3:$H$5000<=NOW())+NOW()*(Dosage!$H$3:$H$5000>NOW()))-(Dosage!$B$3:$B$5000*(Dosage!$B$3:$B$5000>=$E3)+$E3*(Dosage!$B$3:$B$5000<$E3)))>0)*((Dosage!$H$3:$H$5000*(Dosage!$H$3:$H$5000<=NOW())+NOW()*(Dosage!$H$3:$H$5000>NOW()))-(Dosage!$B$3:$B$5000*(Dosage!$B$3:$B$5000>=$E3)+$E3*(Dosage!$B$3:$B$5000<$E3)))*Dosage!$F$3:$F$5000)) -> 0 | I3: =IF(OR($A3="",$E3=""),"",MIN($C3,MAX(0,$F3+$G3-$H3))) -> 1222.8 | J3: =IF(OR($I3="",$C3="",$C3=0),"",$I3/$C3) -> 0.80980132 | K3: =IF(OR($I3="",$D3="",$D3=0),"",$I3/$D3) -> 10.19 | L3: =IF($K3="","",TODAY()+$K3) -> 46289.19 | N3: =IF($J3="","",MIN(1,$J3)) -> 0.80980132 | O3: =IF($J3="","",MAX(0,1-$J3)) -> 0.19019868
